Workbook
Name __FDS_HYPERLINK_TOGGLE_STATE__: "ON"
Name _Order1: 0
Name _Order2: 0
Name a: -15987005.5299987
Name ADM: #REF!
Name ADM: #REF!
Name ADM: #REF!
Name ADM: #REF!
Name ADM: #REF!
Name ADM: #REF!
Name ADM: [0]!ADM
Name ALPHA: #REF!
Name ALPHA: #REF!
Name ALPHA: #REF!
Name ALPHA: #REF!
Name ALPHA: #REF!
Name ALPHA: #REF!
Name Amountin2: "Thousands"
Name AnoDoCalendário: #REF!
Name AnoDoCalendário: #REF!
Name AnoDoCalendário: #REF!
Name Ativo: #REF!
Name Ativo: #REF!
Name Ativo: #REF!
Name Ativo: #REF!
Name AV: #REF!
Name Balanço: #REF!
Name Balanço: #REF!
Name Balanço: #REF!
Name Balanço: #REF!
Name BaseYear: #REF!
Name BaseYear: #REF!
Name BaseYear: #REF!
Name BBQ: #REF!
Name BD_Fluxo_Entradas: #REF!
Name BD_Fluxo_Entradas: #REF!
Name BD_Fluxo_Entradas: #REF!
Name BD_Fluxo_Entradas: #REF!
Name BD_Fluxo_Entradas: #REF!
Name BD_Fluxo_Entradas: #REF!
Name BD_Fluxo_Entradas: #REF!
Name BD_Fluxo_Saidas: #REF!
Name BD_Fluxo_Saidas: #REF!
Name BD_Fluxo_Saidas: #REF!
Name BD_Fluxo_Saidas: #REF!
Name BD_Fluxo_Saidas: #REF!
Name BD_Fluxo_Saidas: #REF!
Name BD_Fluxo_Saidas: #REF!
Name BH: #REF!
Name BreakComercial: #REF!
Name BreakComercial: '04 -Base Orçado 2026'!BreakComercial
Name BreakComercial: #REF!
Name BreakComercial: #REF!
Name BreakComercial: 'Base Realizado'!BreakComercial
Name BreakComercial: #REF!
Name BreakComercial: '04 -Base Orçado 2026'!BreakComercial
Name BS: #REF!
Name BS_Deferred_Taxes: #REF!
Name BS_Deferred_Taxes: #REF!
Name BS_Deferred_Taxes: #REF!

Sheet  01-INDIC
B4: INDICADORES DE PERFORMANCE
D7: BD | E7: REAL | G7: BD | H7: REAL | J7: BD | K7: REAL | M7: MEDIA BD | N7: MEDIA REAL | P7: PROJETADO | R7: 2026 X META | T7: GAP 1°TRI | V7: BD | W7: REAL
B8: INDICADORES | D8: BD JAN.26 | E8: REAL JAN.26 | G8: BD FEV.26 | H8: REAL FEV.26 | J8: BD MAR.26 | K8: REAL MAR.26 | M8: JAN-MAR | N8: JAN/MAR | P8: META GLOB | R8: RL x BD_Jan'26 | S8: RL x BD_Fev'26 | T8: =N8 -> JAN/MAR | V8: BD ABR.26 | W8: REAL ABR.26
B9: CMV | D9: =-'03- BD x RE 2026'!BH28 -> 0.32 | E9: =-'03- BD x RE 2026'!BI28 -> 0.44878234 | G9: =-'03- BD x RE 2026'!BJ28 -> 0.32 | H9: =-'03- BD x RE 2026'!BK28 -> 0.3499834 | J9: =-'03- BD x RE 2026'!BL28 -> 0.31896681 | K9: =-'03- BD x RE 2026'!BM28 -> 0.27268283 | M9: =AVERAGE(D9,G9,J9) -> 0.3196556 | N9: =AVERAGE(E9,H9,K9) -> 0.35714953 | P9: =-'03- BD x RE 2026'!BI28 -> 0.44878234 | R9: =E9-D9 -> 0.12878234 | S9: =H9-G9 -> 0.029983403 | T9: =N9-M9 -> 0.037493923 | V9: =-'03- BD x RE 2026'!BN28 -> 0.32 | W9: =-'03- BD x RE 2026'!BO28 -> 0.3900331
B10: PESSOAL | D10: =-'03- BD x RE 2026'!BH44 -> 0.34444628 | E10: =-'03- BD x RE 2026'!BI44 -> 0.26788404 | G10: =-'03- BD x RE 2026'!BJ44 -> 0.27924096 | H10: =-'03- BD x RE 2026'!BK44 -> 0.33623619 | J10: =-'03- BD x RE 2026'!BL44 -> 0.2732448 | K10: =-'03- BD x RE 2026'!BM44 -> 0.25649129 | M10: =AVERAGE(D10,G10,J10) -> 0.29897735 | N10: =AVERAGE(E10,H10,K10) -> 0.2868705 | P10: =-'03- BD x RE 2026'!AT44 -> 0.28475304 | R10: =E10-D10 -> -0.076562237 | S10: =H10-G10 -> 0.056995226 | T10: =N10-M10 -> -0.012106842 | V10: =-'03- BD x RE 2026'!BN44 -> 0.27005862 | W10: =-'03- BD x RE 2026'!BO44 -> 0.25680654
B11: OCUPAÇÃO | D11: =-'03- BD x RE 2026'!BH49 -> 0.039714716 | E11: =-'03- BD x RE 2026'!BI49 -> 0.045645386 | G11: =-'03- BD x RE 2026'!BJ49 -> 0.029151886 | H11: =-'03- BD x RE 2026'!BK49 -> 0.046203079 | J11: =-'03- BD x RE 2026'!BL49 -> 0.028832965 | K11: =-'03- BD x RE 2026'!BM49 -> 0.029023396 | M11: =AVERAGE(D11,G11,J11) -> 0.032566522 | N11: =AVERAGE(E11,H11,K11) -> 0.04029062 | P11: =-'03- BD x RE 2026'!AT49 -> 0.029719036 | R11: =E11-D11 -> 0.0059306699 | S11: =H11-G11 -> 0.017051194 | T11: =N11-M11 -> 0.007724098 | V11: =-'03- BD x RE 2026'!BN49 -> 0.028193278 | W11: =-'03- BD x RE 2026'!BO49 -> 0.030127141
B12: UTILIDADES/ CONSUMO | D12: =-'03- BD x RE 2026'!BH50 -> 0.027 | E12: =-'03- BD x RE 2026'!BI50 -> 0.039432855 | G12: =-'03- BD x RE 2026'!BJ50 -> 0.023893805 | H12: =-'03- BD x RE 2026'!BK50 -> 0.037155091 | J12: =-'03- BD x RE 2026'!BL50 -> 0.023816659 | K12: =-'03- BD x RE 2026'!BM50 -> 0.022394108 | M12: =AVERAGE(D12,G12,J12) -> 0.024903488 | N12: =AVERAGE(E12,H12,K12) -> 0.032994018 | P12: =-'03- BD x RE 2026'!AT50 -> 0.024062252 | R12: =E12-D12 -> 0.012432855 | S12: =H12-G12 -> 0.013261286 | T12: =N12-M12 -> 0.00809053 | V12: =-'03- BD x RE 2026'!BN50 -> 0.023893805 | W12: =-'03- BD x RE 2026'!BO50 -> 0.026359761
B13: OPERAÇÃO | D13: =-'03- BD x RE 2026'!BH51 -> 0.11249162 | E13: =-'03- BD x RE 2026'!BI51 -> 0.1554671 | G13: =-'03- BD x RE 2026'!BJ51 -> 0.079372646 | H13: =-'03- BD x RE 2026'!BK51 -> 0.14694741 | J13: =-'03- BD x RE 2026'!BL51 -> 0.078603017 | K13: =-'03- BD x RE 2026'!BM51 -> 0.099958575 | M13: =AVERAGE(D13,G13,J13) -> 0.090155762 | N13: =AVERAGE(E13,H13,K13) -> 0.13412436 | P13: =-'03- BD x RE 2026'!AT51 -> 0.08181988 | R13: =E13-D13 -> 0.042975478 | S13: =H13-G13 -> 0.067574766 | T13: =N13-M13 -> 0.043968601 | V13: =-'03- BD x RE 2026'!BN51 -> 0.077183524 | W13: =-'03- BD x RE 2026'!BO51 -> 0.11012975
B14: MANUTENÇÃO E CONSERVAS | D14: =-'03- BD x RE 2026'!BH52 -> 0.01 | E14: =-'03- BD x RE 2026'!BI52 -> 0.03744011 | G14: =-'03- BD x RE 2026'!BJ52 -> 0.0088495575 | H14: =-'03- BD x RE 2026'!BK52 -> 0.017819199 | J14: =-'03- BD x RE 2026'!BL52 -> 0.0088209847 | K14: =-'03- BD x RE 2026'!BM52 -> 0.0077245912 | M14: =AVERAGE(D14,G14,J14) -> 0.0092235141 | N14: =AVERAGE(E14,H14,K14) -> 0.020994633 | P14: =-'03- BD x RE 2026'!AT52 -> 0.0089119453 | R14: =E14-D14 -> 0.02744011 | S14: =H14-G14 -> 0.0089696412 | T14: =N14-M14 -> 0.011771119 | V14: =-'03- BD x RE 2026'!BN52 -> 0.0088495575 | W14: =-'03- BD x RE 2026'!BO52 -> 0.0097107564
B15: ADMINISTRATIVA | D15: =-'03- BD x RE 2026'!BH57 -> 0.10775389 | E15: =-'03- BD x RE 2026'!BI57 -> 0.11996838 | G15: =-'03- BD x RE 2026'!BJ57 -> 0.076194079 | H15: =-'03- BD x RE 2026'!BK57 -> 0.095321122 | J15: =-'03- BD x RE 2026'!BL57 -> 0.075493153 | K15: =-'03- BD x RE 2026'!BM57 -> 0.072262988 | M15: =AVERAGE(D15,G15,J15) -> 0.086480376 | N15: =AVERAGE(E15,H15,K15) -> 0.095850829 | P15: =-'03- BD x RE 2026'!AT57 -> 0.078485779 | R15: =E15-D15 -> 0.012214485 | S15: =H15-G15 -> 0.019127042 | T15: =N15-M15 -> 0.0093704539 | V15: =-'03- BD x RE 2026'!BN57 -> 0.074254164 | W15: =-'03- BD x RE 2026'!BO57 -> 0.047794225
B16: MARKETING | D16: =-'03- BD x RE 2026'!BH58 -> 0.02 | E16: =-'03- BD x RE 2026'!BI58 -> 0.055042652 | G16: =-'03- BD x RE 2026'!BJ58 -> 0.02 | H16: =-'03- BD x RE 2026'!BK58 -> 0.028502258 | J16: =-'03- BD x RE 2026'!BL58 -> 0.019935426 | K16: =-'03- BD x RE 2026'!BM58 -> 0.014590393 | M16: =AVERAGE(D16,G16,J16) -> 0.019978475 | N16: =AVERAGE(E16,H16,K16) -> 0.032711768 | P16: =-'03- BD x RE 2026'!AT58 -> 0.019994347 | R16: =E16-D16 -> 0.035042652 | S16: =H16-G16 -> 0.0085022582 | T16: =N16-M16 -> 0.012733293 | V16: =-'03- BD x RE 2026'!BN58 -> 0.02 | W16: =-'03- BD x RE 2026'!BO58 -> 0.028668855
B17: TX CARTÕES | D17: =-'03- BD x RE 2026'!BH59 -> 0.021034109 | E17: =-'03- BD x RE 2026'!BI59 -> 0.013082143 | G17: =-'03- BD x RE 2026'!BJ59 -> 0.02 | H17: =-'03- BD x RE 2026'!BK59 -> 0.012408581 | J17: =-'03- BD x RE 2026'!BL59 -> 0.018554156 | K17: =-'03- BD x RE 2026'!BM59 -> 0.010950112 | M17: =AVERAGE(D17,G17,J17) -> 0.019862755 | N17: =AVERAGE(E17,H17,K17) -> 0.012146945 | P17: =-'03- BD x RE 2026'!AT59 -> 0.031082644 | R17: =E17-D17 -> -0.0079519667 | S17: =H17-G17 -> -0.0075914194 | T17: =N17-M17 -> -0.0077158101 | V17: =-'03- BD x RE 2026'!BN59 -> 0.018614256 | W17: =-'03- BD x RE 2026'!BO59 -> 0.011283126
B19: EBITDA | D19: ='02-Res M'!D30 -> -0.0024406215 | E19: ='02-Res M'!F30 -> -0.18274501 | G19: ='02-Res M'!H30 -> 0.14329707 | H19: ='02-Res M'!J30 -> -0.070576332 | J19: ='02-Res M'!J30 -> -0.070576332 | K19: ='02-Res M'!L30 -> 0.15373203 | M19: =AVERAGE(D19,G19,J19) -> 0.023426704 | N19: =E19 -> -0.18274501 | P19: ='03- BD x RE 2026'!AT62 -> 0.12126151 | R19: =P19-E19 -> 0.30400652 | S19: =P19-H19 -> 0.19183785 | T19: =P19-N19 -> 0.30400652 | V19: ='02-Res M'!V30 -> 0 | W19: ='02-Res M'!X30 -> 0
B20: RESULTADO LÍQUIDO | D20: ='02-Res M'!D41 -> -0.010020481 | E20: ='02-Res M'!F41 -> -0.18446701 | G20: ='02-Res M'!H41 -> 0.13571721 | H20: ='02-Res M'!J41 -> -0.071091259 | J20: ='02-Res M'!J41 -> -0.071091259 | K20: ='02-Res M'!L41 -> 0.14617664 | M20: =AVERAGE(D20,G20,J20) -> 0.018201822 | N20: =AVERAGE(E20,H20,K20) -> -0.036460542 | P20: ='03- BD x RE 2026'!AT72 -> 0.1136838 | R20: =P20-E20 -> 0.29815081 | S20: =P20-H20 -> 0.18477506 | T20: =N20-M20 -> -0.054662364 | V20: ='03- BD x RE 2026'!M73 -> 0.15137294 | W20: ='03- BD x RE 2026'!N73 -> 0.089086739
B22: COMPARATIVOS | D22: BUDGET | E22: REAL | G22: BUDGET | H22: REAL | J22: BUDGET | K22: REAL | M22: Total. BD Tri | N22: Total Real Tri | T22: 1º TRI | V22: BUDGET | W22: REAL
B24: ='[1]02-Res M'!B15 -> Receita Líquida | D24: ='03- BD x RE 2026'!D24 -> 1603133.7 | E24: ='03- BD x RE 2026'!E24 -> 1338861.7 | G24: ='03- BD x RE 2026'!G24 -> 2460755.4 | H24: ='03- BD x RE 2026'!H24 -> 1507127.3 | J24: ='03- BD x RE 2026'!J24 -> 2487973.7 | K24: ='03- BD x RE 2026'!K24 -> 2383612.2 | M24: =SUM(A24,G24,J24) -> 4948729.1 | N24: =SUM(B24,H24,K24) -> 3890739.5 | T24: =M24-L24 -> 4948729.1 | V24: ='03- BD x RE 2026'!M24 -> 2544424.3 | W24: ='03- BD x RE 2026'!N24 -> 2296285.6
B26: Resultado Líquido BD x REAL | D26: ='03- BD x RE 2026'!D72 -> -16064.17 | E26: ='03- BD x RE 2026'!E72 -> -246975.82 | G26: ='03- BD x RE 2026'!G72 -> 333966.85 | H26: ='03- BD x RE 2026'!H72 -> -108396.03 | J26: ='03- BD x RE 2026'!J72 -> 363683.65 | K26: ='03- BD x RE 2026'!K72 -> 508314.52 | M26: =SUM(A26,G26,J26) -> 697650.5 | N26: =SUM(B26,H26,K26) -> 399918.48 | T26: =M26-L26 -> 697650.5 | V26: ='03- BD x RE 2026'!M72 -> 385156.98 | W26: ='03- BD x RE 2026'!N72 -> 204568.6

Sheet 02-Res M
B4: COMPARATIVO REAL VS ORÇAMENTO 2026 | U4: INDICES
U5: PARTICIPAÇÃO | Y5: PARTICIPAÇÃO
D6: BD JAN'26 | F6: REAL JAN'26 | H6: BD FEV'26 | J6: REAL FEV'26 | L6: BD MAR26 | N6: BD MAR26 | P6: V' RE X BD JAN/26 | R6: V' RE X BD JAN/26 | T6: V' RE X BD MAR/26 | U6: BD X MAR'26 | AG6: =U5 -> PARTICIPAÇÃO
B8: Clientes | D8: ='03- BD x RE 2026'!D7/1000 -> 5.7864418 | F8: ='03- BD x RE 2026'!E7/1000 -> 4.761 | H8: ='03- BD x RE 2026'!G7/1000 -> 7.8601684 | J8: ='03- BD x RE 2026'!H7/1000 -> 4.661 | L8: ='03- BD x RE 2026'!J7/1000 -> 7.9214504 | N8: ='03- BD x RE 2026'!K7/1000 -> 6.592 | P8: =IF(ISERROR($F8/D8-1),"-",($F8/D8-1)) -> -0.17721457 | R8: =IF(ISERROR($J8/J8-1),"-",($H8/J8-1)) -> 0.68636953 | T8: =IF(ISERROR($L8/N8-1),"-",($L8/N8-1)) -> 0.20167633
B9: Ticket Médio FB | D9: =IF(ISERROR(D11/D8),0,(D11/D8)) -> 300 | F9: =IF(ISERROR(F11/F8),0,(F11/F8)) -> 292.02877 | H9: =IF(ISERROR(H11/H8),0,(H11/H8)) -> 339 | J9: =IF(ISERROR(J11/J8),0,(J11/J8)) -> 327.94552 | L9: =IF(ISERROR(L11/L8),0,(L11/L8)) -> 340.01408 | N9: =IF(ISERROR(N11/N8),0,(N11/N8)) -> 370.68215 | P9: =IF(ISERROR($F9/D9-1),"-",($F9/D9-1)) -> -0.026570769 | R9: =IF(ISERROR($H9/J9-1),"-",($H9/J9-1)) -> 0.033708288 | T9: =IF(ISERROR($L9/N9-1),"-",($L9/N9-1)) -> -0.082734151
R10: =IF(ISERROR($H10/J10-1),"-",($H10/J10-1)) -> - | T10: =IF(ISERROR($H10/K10-1),"-",($H10/K10-1)) -> -
B11: Faturamento Bruto | D11: ='03- BD x RE 2026'!D10/1000 -> 1735.9325 | F11: ='03- BD x RE 2026'!E10/1000 -> 1390.349 | H11: ='03- BD x RE 2026'!G10/1000 -> 2664.5971 | J11: ='03- BD x RE 2026'!H10/1000 -> 1528.5541 | L11: ='03- BD x RE 2026'!J10/1000 -> 2693.4047 | N11: ='03- BD x RE 2026'!K10/1000 -> 2443.5368 | P11: =IF(ISERROR($F11/D11-1),"-",($F11/D11-1)) -> -0.19907661 | R11: =IF(ISERROR($H11/J11-1),"-",($H11/J11-1)) -> 0.74321416 | T11: =IF(ISERROR($L11/N11-1),"-",($L11/N11-1)) -> 0.10225666 | U11: JAN'26 | Y11: FEV'26 | AC11: Mar'26
R12: =IF(ISERROR($H12/J12-1),"-",($H12/J12-1)) -> -
B13: Impostos (ICMS/PIS/COFINS) | D13: ='03- BD x RE 2026'!D19/1000 -> -132.79884 | F13: ='03- BD x RE 2026'!E19/1000 -> -51.48725 | H13: ='03- BD x RE 2026'!G19/1000 -> -203.84168 | J13: ='03- BD x RE 2026'!H19/1000 -> -21.42681 | L13: ='03- BD x RE 2026'!J19/1000 -> -205.43093 | N13: ='03- BD x RE 2026'!K19/1000 -> -59.92454 | P13: =IF(ISERROR($F13/D13-1),"-",($F13/D13-1)) -> -0.61229142 | R13: =IF(ISERROR($H13/J13-1),"-",($H13/J13-1)) -> 8.5133936 | T13: =IF(ISERROR($L13/N13-1),"-",($L13/N13-1)) -> 2.4281604
R14: =IF(ISERROR($H14/J14-1),"-",($H14/J14-1)) -> -
B15: Receita Líquida | D15: =D11+D13 -> 1603.1337 | F15: =F11+F13 -> 1338.8617 | H15: =H11+H13 -> 2460.7554 | J15: =J11+J13 -> 1507.1273 | L15: =L11+L13 -> 2487.9737 | N15: =N11+N13 -> 2383.6122 | P15: =IF(ISERROR($F15/D15-1),"-",($F15/D15-1)) -> -0.16484713 | R15: =IF(ISERROR($H15/J15-1),"-",($H15/J15-1)) -> 0.63274562 | T15: =IF(ISERROR($L15/N15-1),"-",($L15/N15-1)) -> 0.043782923 | U15: PART% BD | W15: PART% REAL | Y15: PART% BD | AA15: PART% REAL | AC15: PART% BD | AE15: PART% REAL
R16: =IF(ISERROR($H16/J16-1),"-",($H16/J16-1)) -> -
B17: ='[2]2 DRE '!A27 -> CUSTOS/DESPESAS | D17: =SUM(D18:D23) -> -1368.5193 | F17: =SUM(F18:F23) -> -1331.7013 | H17: =SUM(H18:H23) -> -1822.2112 | J17: =SUM(J18:J23) -> -1408.1759 | L17: =SUM(L18:L23) -> -1821.9064 | N17: =SUM(N18:N23) -> -1640.5802 | P17: =IF(ISERROR($F17/D17-1),"-",($F17/D17-1)) -> -0.02690354 | R17: =IF(ISERROR($H17/J17-1),"-",($H17/J17-1)) -> 0.29402244 | T17: =IF(ISERROR($L17/N17-1),"-",($L17/N17-1)) -> 0.11052568 | U17: =IF(ISERROR($D17/$D$15),"-",($D17/$D$15)) -> -0.85365262 | W17: =IF(ISERROR(F17/F$15),"-",(F17/F$15)) -> -0.99465184 | Y17: =IF(ISERROR($H17/$H$15),"-",($H17/$H$15)) -> -0.74050886 | AA17: =IF(ISERROR(J17/J$15),"-",(J17/J$15)) -> -0.93434437 | AC17: =IF(ISERROR($L17/$L$15),"-",($L17/$L$15)) -> -0.73228524 | AE17: =IF(ISERROR(N17/N$15),"-",(N17/N$15)) -> -0.68827479 | AG17: Impacto
B18: CMV | D18: ='03- BD x RE 2026'!D28/1000 -> -513.00279 | F18: ='03- BD x RE 2026'!E28/1000 -> -600.8575 | H18: ='03- BD x RE 2026'!G28/1000 -> -787.44173 | J18: ='03- BD x RE 2026'!H28/1000 -> -527.46952 | L18: ='03- BD x RE 2026'!J28/1000 -> -793.58104 | N18: ='03- BD x RE 2026'!K28/1000 -> -649.97013 | P18: =IF(ISERROR($F18/D18-1),"-",($F18/D18-1)) -> 0.17125582 | R18: =IF(ISERROR($H18/J18-1),"-",($H18/J18-1)) -> 0.49286679 | T18: =IF(ISERROR($L18/N18-1),"-",($L18/N18-1)) -> 0.22095002 | U18: =IF(ISERROR($D18/$D$15),"-",($D18/$D$15)) -> -0.32 | W18: =IF(ISERROR(F18/F$15),"-",(F18/F$15)) -> -0.44878234 | Y18: =IF(ISERROR($H18/$H$15),"-",($H18/$H$15)) -> -0.32 | AA18: =IF(ISERROR(J18/J$15),"-",(J18/J$15)) -> -0.3499834 | AC18: =IF(ISERROR($L18/$L$15),"-",($L18/$L$15)) -> -0.31896681 | AE18: =IF(ISERROR(N18/N$15),"-",(N18/N$15)) -> -0.27268283 | AG18: =-W18*AE18 -> -0.12237524
B19: Pessoal | D19: ='03- BD x RE 2026'!D44/1000 -> -552.19344 | F19: ='03- BD x RE 2026'!E44/1000 -> -358.65969 | H19: ='03- BD x RE 2026'!G44/1000 -> -687.1437 | J19: ='03- BD x RE 2026'!H44/1000 -> -506.75072 | L19: ='03- BD x RE 2026'!J44/1000 -> -679.82589 | N19: ='03- BD x RE 2026'!K44/1000 -> -611.37576 | P19: =IF(ISERROR($F19/D19-1),"-",($F19/D19-1)) -> -0.3504818 | R19: =IF(ISERROR($H19/J19-1),"-",($H19/J19-1)) -> 0.35597973 | T19: =IF(ISERROR($L19/N19-1),"-",($L19/N19-1)) -> 0.11196081 | U19: =IF(ISERROR($D19/$D$15),"-",($D19/$D$15)) -> -0.34444628 | W19: =IF(ISERROR(F19/F$15),"-",(F19/F$15)) -> -0.26788404 | Y19: =IF(ISERROR($H19/$H$15),"-",($H19/$H$15)) -> -0.27924096 | AA19: =IF(ISERROR(J19/J$15),"-",(J19/J$15)) -> -0.33623619 | AC19: =IF(ISERROR($L19/$L$15),"-",($L19/$L$15)) -> -0.2732448 | AE19: =IF(ISERROR(N19/N$15),"-",(N19/N$15)) -> -0.25649129 | AG19: =-W19*AE19 -> -0.068709922
B20: Ocupação | D20: ='03- BD x RE 2026'!D49/1000 -> -63.668 | F20: ='03- BD x RE 2026'!E49/1000 -> -61.11286 | H20: ='03- BD x RE 2026'!G49/1000 -> -71.73566 | J20: ='03- BD x RE 2026'!H49/1000 -> -69.63392 | L20: ='03- BD x RE 2026'!J49/1000 -> -71.73566 | N20: ='03- BD x RE 2026'!K49/1000 -> -69.18052 | P20: =IF(ISERROR($F20/D20-1),"-",($F20/D20-1)) -> -0.040132249 | R20: =IF(ISERROR($H20/J20-1),"-",($H20/J20-1)) -> 0.030182704 | T20: =IF(ISERROR($L20/N20-1),"-",($L20/N20-1)) -> 0.036934386 | U20: =IF(ISERROR($D20/$D$15),"-",($D20/$D$15)) -> -0.039714716 | W20: =IF(ISERROR(F20/F$15),"-",(F20/F$15)) -> -0.045645386 | Y20: =IF(ISERROR($H20/$H$15),"-",($H20/$H$15)) -> -0.029151886 | AA20: =IF(ISERROR(J20/J$15),"-",(J20/J$15)) -> -0.046203079 | AC20: =IF(ISERROR($L20/$L$15),"-",($L20/$L$15)) -> -0.028832965 | AE20: =IF(ISERROR(N20/N$15),"-",(N20/N$15)) -> -0.029023396 | AG20: =-W20*AE20 -> -0.0013247841
B21: Utilidades/ Consumo | D21: ='03- BD x RE 2026'!D50/1000 -> -43.28461 | F21: ='03- BD x RE 2026'!E50/1000 -> -52.79514 | H21: ='03- BD x RE 2026'!G50/1000 -> -58.796811 | J21: ='03- BD x RE 2026'!H50/1000 -> -55.99745 | L21: ='03- BD x RE 2026'!J50/1000 -> -59.255221 | N21: ='03- BD x RE 2026'!K50/1000 -> -53.37887 | P21: =IF(ISERROR($F21/D21-1),"-",($F21/D21-1)) -> 0.21972082 | R21: =IF(ISERROR($H21/J21-1),"-",($H21/J21-1)) -> 0.04999086 | T21: =IF(ISERROR($L21/N21-1),"-",($L21/N21-1)) -> 0.11008759 | U21: =IF(ISERROR($D21/$D$15),"-",($D21/$D$15)) -> -0.027 | W21: =IF(ISERROR(F21/F$15),"-",(F21/F$15)) -> -0.039432855 | Y21: =IF(ISERROR($H21/$H$15),"-",($H21/$H$15)) -> -0.023893805 | AA21: =IF(ISERROR(J21/J$15),"-",(J21/J$15)) -> -0.037155091 | AC21: =IF(ISERROR($L21/$L$15),"-",($L21/$L$15)) -> -0.023816659 | AE21: =IF(ISERROR(N21/N$15),"-",(N21/N$15)) -> -0.022394108 | AG21: =-W21*AE21 -> -0.00088306362
B22: Operação | D22: ='03- BD x RE 2026'!D51/1000 -> -180.33911 | F22: ='03- BD x RE 2026'!E51/1000 -> -208.14895 | H22: ='03- BD x RE 2026'!G51/1000 -> -195.31667 | J22: ='03- BD x RE 2026'!H51/1000 -> -221.46845 | L22: ='03- BD x RE 2026'!J51/1000 -> -195.56224 | N22: ='03- BD x RE 2026'!K51/1000 -> -238.26248 | P22: =IF(ISERROR($F22/D22-1),"-",($F22/D22-1)) -> 0.15420858 | R22: =IF(ISERROR($H22/J22-1),"-",($H22/J22-1)) -> -0.11808355 | T22: =IF(ISERROR($L22/N22-1),"-",($L22/N22-1)) -> -0.17921512 | U22: =IF(ISERROR($D22/$D$15),"-",($D22/$D$15)) -> -0.11249162 | W22: =IF(ISERROR(F22/F$15),"-",(F22/F$15)) -> -0.1554671 | Y22: =IF(ISERROR($H22/$H$15),"-",($H22/$H$15)) -> -0.079372646 | AA22: =IF(ISERROR(J22/J$15),"-",(J22/J$15)) -> -0.14694741 | AC22: =IF(ISERROR($L22/$L$15),"-",($L22/$L$15)) -> -0.078603017 | AE22: =IF(ISERROR(N22/N$15),"-",(N22/N$15)) -> -0.099958575 | AG22: =-W22*AE22 -> -0.01554027
B23: Manutenção e Conservação | D23: ='03- BD x RE 2026'!D52/1000 -> -16.031337 | F23: ='03- BD x RE 2026'!E52/1000 -> -50.12713 | H23: ='03- BD x RE 2026'!G52/1000 -> -21.776597 | J23: ='03- BD x RE 2026'!H52/1000 -> -26.8558 | L23: ='03- BD x RE 2026'!J52/1000 -> -21.946378 | N23: ='03- BD x RE 2026'!K52/1000 -> -18.41243 | P23: =IF(ISERROR($F23/D23-1),"-",($F23/D23-1)) -> 2.1268215 | R23: =IF(ISERROR($H23/J23-1),"-",($H23/J23-1)) -> -0.18912873 | T23: =IF(ISERROR($L23/N23-1),"-",($L23/N23-1)) -> 0.19193274 | U23: =IF(ISERROR($D23/$D$15),"-",($D23/$D$15)) -> -0.01 | W23: =IF(ISERROR(F23/F$15),"-",(F23/F$15)) -> -0.03744011 | Y23: =IF(ISERROR($H23/$H$15),"-",($H23/$H$15)) -> -0.0088495575 | AA23: =IF(ISERROR(J23/J$15),"-",(J23/J$15)) -> -0.017819199 | AC23: =IF(ISERROR($L23/$L$15),"-",($L23/$L$15)) -> -0.0088209847 | AE23: =IF(ISERROR(N23/N$15),"-",(N23/N$15)) -> -0.0077245912 | AG23: =-W23*AE23 -> -0.00028920955
B24: ='[2]2 DRE '!A52 -> DESPESAS ADMINISTRATIVAS | D24: =SUM(D25:D27) -> -238.52706 | F24: =SUM(F25:F27) -> -251.83075 | H24: =SUM(H25:H27) -> -285.92521 | J24: =SUM(J25:J27) -> -205.3189 | L24: =SUM(L25:L27) -> -283.58605 | N24: =SUM(N25:N27) -> -233.1256 | P24: =IF(ISERROR($F24/D24-1),"-",($F24/D24-1)) -> 0.055774327 | R24: =IF(ISERROR($H24/J24-1),"-",($H24/J24-1)) -> 0.39259079 | T24: =IF(ISERROR($L24/N24-1),"-",($L24/N24-1)) -> 0.21645176 | U24: =IF(ISERROR($D24/$D$15),"-",($D24/$D$15)) -> -0.148788 | W24: =IF(ISERROR(F24/F$15),"-",(F24/F$15)) -> -0.18809317 | Y24: =IF(ISERROR($H24/$H$15),"-",($H24/$H$15)) -> -0.11619408 | AA24: =IF(ISERROR(J24/J$15),"-",(J24/J$15)) -> -0.13623196 | AC24: =IF(ISERROR($L24/$L$15),"-",($L24/$L$15)) -> -0.11398273 | AE24: =IF(ISERROR(N24/N$15),"-",(N24/N$15)) -> -0.097803493 | AG24: =AE24-W24 -> 0.090289681
B25: Administrativa | D25: ='03- BD x RE 2026'!D57/1000 -> -172.7439 | F25: ='03- BD x RE 2026'!E57/1000 -> -160.62107 | H25: ='03- BD x RE 2026'!G57/1000 -> -187.49499 | J25: ='03- BD x RE 2026'!H57/1000 -> -143.66106 | L25: ='03- BD x RE 2026'!J57/1000 -> -187.82498 | N25: ='03- BD x RE 2026'!K57/1000 -> -172.24694 | P25: =IF(ISERROR($F25/D25-1),"-",($F25/D25-1)) -> -0.070178048 | R25: =IF(ISERROR($H25/J25-1),"-",($H25/J25-1)) -> 0.30512049 | T25: =IF(ISERROR($L25/N25-1),"-",($L25/N25-1)) -> 0.090440159 | U25: =IF(ISERROR($D25/$D$15),"-",($D25/$D$15)) -> -0.10775389 | W25: =IF(ISERROR(F25/F$15),"-",(F25/F$15)) -> -0.11996838 | Y25: =IF(ISERROR($H25/$H$15),"-",($H25/$H$15)) -> -0.076194079 | AA25: =IF(ISERROR(J25/J$15),"-",(J25/J$15)) -> -0.095321122 | AC25: =IF(ISERROR($L25/$L$15),"-",($L25/$L$15)) -> -0.075493153 | AE25: =IF(ISERROR(N25/N$15),"-",(N25/N$15)) -> -0.072262988 | AG25: =-W25*AE25 -> -0.0086692735
B26: Marketing | D26: ='03- BD x RE 2026'!D58/1000 -> -32.062674 | F26: ='03- BD x RE 2026'!E58/1000 -> -73.6945 | H26: ='03- BD x RE 2026'!G58/1000 -> -49.215108 | J26: ='03- BD x RE 2026'!H58/1000 -> -42.95653 | L26: ='03- BD x RE 2026'!J58/1000 -> -49.598815 | N26: ='03- BD x RE 2026'!K58/1000 -> -34.77784 | P26: =IF(ISERROR($D26/F26-1),"-",($D26/F26-1)) -> -0.56492446 | R26: =IF(ISERROR($H26/J26-1),"-",($H26/J26-1)) -> 0.14569562 | T26: =IF(ISERROR($L26/N26-1),"-",($L26/N26-1)) -> 0.42616145 | U26: =IF(ISERROR($D26/$D$15),"-",($D26/$D$15)) -> -0.02 | W26: =IF(ISERROR(F26/F$15),"-",(F26/F$15)) -> -0.055042652 | Y26: =IF(ISERROR($H26/$H$15),"-",($H26/$H$15)) -> -0.02 | AA26: =IF(ISERROR(J26/J$15),"-",(J26/J$15)) -> -0.028502258 | AC26: =IF(ISERROR($L26/$L$15),"-",($L26/$L$15)) -> -0.019935426 | AE26: =IF(ISERROR(N26/N$15),"-",(N26/N$15)) -> -0.014590393 | AG26: =-W26*AE26 -> -0.00080309395
B27: Taxa Cartão Crédito | D27: ='03- BD x RE 2026'!D59/1000 -> -33.72049 | F27: ='03- BD x RE 2026'!E59/1000 -> -17.51518 | H27: ='03- BD x RE 2026'!G59/1000 -> -49.215108 | J27: ='03- BD x RE 2026'!H59/1000 -> -18.70131 | L27: ='03- BD x RE 2026'!J59/1000 -> -46.162252 | N27: ='03- BD x RE 2026'!K59/1000 -> -26.10082 | P27: =IF(ISERROR($F27/D27-1),"-",($F27/D27-1)) -> -0.48057753 | R27: =IF(ISERROR($H27/J27-1),"-",($H27/J27-1)) -> 1.6316396 | T27: =IF(ISERROR($L27/N27-1),"-",($L27/N27-1)) -> 0.76861309 | U27: =IF(ISERROR($D27/$D$15),"-",($D27/$D$15)) -> -0.021034109 | W27: =IF(ISERROR(F27/F$15),"-",(F27/F$15)) -> -0.013082143 | Y27: =IF(ISERROR($H27/$H$15),"-",($H27/$H$15)) -> -0.02 | AA27: =IF(ISERROR(J27/J$15),"-",(J27/J$15)) -> -0.012408581 | AC27: =IF(ISERROR($L27/$L$15),"-",($L27/$L$15)) -> -0.018554156 | AE27: =IF(ISERROR(N27/N$15),"-",(N27/N$15)) -> -0.010950112 | AG27: =-W27*AE27 -> -0.00014325092
R28: =IF(ISERROR($H28/J28-1),"-",($H28/J28-1)) -> - | T28: =IF(ISERROR($L28/N28-1),"-",($L28/N28-1)) -> - | U28: =IF(ISERROR($D28/$D$15),"-",($D28/$D$15)) -> 0 | Y28: =IF(ISERROR($H28/$H$15),"-",($H28/$H$15)) -> 0 | AC28: =IF(ISERROR($L28/$L$15),"-",($L28/$L$15)) -> 0 | AE28: =IF(ISERROR(N28/N$15),"-",(N28/N$15)) -> 0 | AG28: =-W28*AE28 -> 0
B29: LAJIDA | D29: =D15+D17+D24 -> -3.9126425 | F29: =F15+F17+F24 -> -244.6703 | H29: =H15+H17+H24 -> 352.61903 | J29: =J15+J17+J24 -> -106.36751 | L29: =L15+L17+L24 -> 382.48125 | N29: =N15+N17+N24 -> 509.90643 | P29: =IF(ISERROR($F29/D29-1),"-",($F29/D29-1)) -> 61.533262 | R29: =IF(ISERROR($H29/J29-1),"-",($H29/J29-1)) -> -4.3151008 | T29: =IF(ISERROR($L29/N29-1),"-",($L29/N29-1)) -> -0.24989914 | U29: =IF(ISERROR($D29/$D$15),"-",($D29/$D$15)) -> -0.0024406215 | W29: =IF(ISERROR(F29/F$15),"-",(F29/F$15)) -> -0.18274501 | Y29: =IF(ISERROR($H29/$H$15),"-",($H29/$H$15)) -> 0.14329707 | AA29: =IF(ISERROR(J29/J$15),"-",(J29/J$15)) -> -0.070576332 | AC29: =IF(ISERROR($L29/$L$15),"-",($L29/$L$15)) -> 0.15373203 | AE29: =IF(ISERROR(N29/N$15),"-",(N29/N$15)) -> 0.21392172 | AG29: =AE29-W29 -> 0.39666673
B30: MARGEM EBITDA | D30: =IF(ISERROR(D29/D15),0,(D29/D15)) -> -0.0024406215 | F30: =IF(ISERROR(F29/F15),0,(F29/F15)) -> -0.18274501 | H30: =IF(ISERROR(H29/H15),0,(H29/H15)) -> 0.14329707 | J30: =IF(ISERROR(J29/J15),0,(J29/J15)) -> -0.070576332 | L30: =IF(ISERROR(L29/L15),0,(L29/L15)) -> 0.15373203 | N30: =IF(ISERROR(N29/N15),0,(N29/N15)) -> 0.21392172 | P30: =IF(ISERROR($D30/F30-1),"-",($D30/F30-1)) -> -0.98664466 | R30: =IF(ISERROR($H30/J30-1),"-",($H30/J30-1)) -> -3.0303841 | T30: =IF(ISERROR($L30/N30-1),"-",($L30/N30-1)) -> -0.28136316 | U30: =IF(ISERROR($D30/$D$15),"-",($D30/$D$15)) -> -1.5224067e-06 | Y30: =IF(ISERROR($H30/$H$15),"-",($H30/$H$15)) -> 5.8232957e-05 | AC30: =IF(ISERROR($L30/$L$15),"-",($L30/$L$15)) -> 6.1790054e-05 | AE30: =IF(ISERROR(N30/N$15),"-",(N30/N$15)) -> 8.9746864e-05 | AG30: =-W30*AE30 -> 0
R31: =IF(ISERROR($H31/J31-1),"-",($H31/J31-1)) -> - | T31: =IF(ISERROR($H31/K31-1),"-",($H31/K31-1)) -> - | U31: =IF(ISERROR($D31/$D$15),"-",($D31/$D$15)) -> 0 | Y31: =IF(ISERROR($H31/$H$15),"-",($H31/$H$15)) -> 0 | AC31: =IF(ISERROR($L31/$L$15),"-",($L31/$L$15)) -> 0 | AE31: =IF(ISERROR(N31/N$15),"-",(N31/N$15)) -> 0 | AG31: =-W31*AE31 -> 0
B32: Depreciação & Amortização | P32: =IF(ISERROR($F32/D32-1),"-",($F32/D32-1)) -> - | R32: =IF(ISERROR($H32/J32-1),"-",($H32/J32-1)) -> - | T32: =IF(ISERROR($H32/K32-1),"-",($H32/K32-1)) -> - | U32: =IF(ISERROR($D32/$D$15),"-",($D32/$D$15)) -> 0 | W32: =IF(ISERROR(F32/F$15),"-",(F32/F$15)) -> 0 | Y32: =IF(ISERROR($H32/$H$15),"-",($H32/$H$15)) -> 0 | AA32: =IF(ISERROR(J32/J$15),"-",(J32/J$15)) -> 0 | AC32: =IF(ISERROR($L32/$L$15),"-",($L32/$L$15)) -> 0 | AE32: =IF(ISERROR(N32/N$15),"-",(N32/N$15)) -> 0 | AG32: =-W32*AE32 -> 0
R33: =IF(ISERROR($H33/J33-1),"-",($H33/J33-1)) -> - | T33: =IF(ISERROR($H33/K33-1),"-",($H33/K33-1)) -> - | U33: =IF(ISERROR($D33/$D$15),"-",($D33/$D$15)) -> 0 | Y33: =IF(ISERROR($H33/$H$15),"-",($H33/$H$15)) -> 0 | AC33: =IF(ISERROR($L33/$L$15),"-",($L33/$L$15)) -> 0 | AE33: =IF(ISERROR(N33/N$15),"-",(N33/N$15)) -> 0 | AG33: =-W33*AE33 -> 0
B34: LAIR | D34: =D29+D32 -> -3.9126425 | F34: =F29+F32 -> -244.6703 | H34: =H29+H32 -> 352.61903 | J34: =J29+J32 -> -106.36751 | L34: =L29+L32 -> 382.48125 | N34: =N29+N32 -> 509.90643 | P34: =IF(ISERROR($F34/D34-1),"-",($F34/D34-1)) -> 61.533262 | R34: =IF(ISERROR($H34/J34-1),"-",($H34/J34-1)) -> -4.3151008 | T34: =IF(ISERROR($L34/N34-1),"-",($L34/N34-1)) -> -0.24989914 | U34: =IF(ISERROR($D34/$D$15),"-",($D34/$D$15)) -> -0.0024406215 | W34: =IF(ISERROR(F34/F$15),"-",(F34/F$15)) -> -0.18274501 | Y34: =IF(ISERROR($H34/$H$15),"-",($H34/$H$15)) -> 0.14329707 | AA34: =IF(ISERROR(J34/J$15),"-",(J34/J$15)) -> -0.070576332 | AC34: =IF(ISERROR($L34/$L$15),"-",($L34/$L$15)) -> 0.15373203 | AE34: =IF(ISERROR(N34/N$15),"-",(N34/N$15)) -> 0.21392172 | AG34: =AE34-W34 -> 0.39666673
B35: MARGEM EBIT | D35: =IF(ISERROR(D34/D15),0,(D34/D15)) -> -0.0024406215 | F35: =IF(ISERROR(F34/F15),0,(F34/F15)) -> -0.18274501 | H35: =IF(ISERROR(H34/H15),0,(H34/H15)) -> 0.14329707 | J35: =IF(ISERROR(J34/J15),0,(J34/J15)) -> -0.070576332 | L35: =IF(ISERROR(L34/L15),0,(L34/L15)) -> 0.15373203 | N35: =IF(ISERROR(N34/N15),0,(N34/N15)) -> 0.21392172 | P35: =IF(ISERROR($D35/F35-1),"-",($D35/F35-1)) -> -0.98664466 | R35: =IF(ISERROR($H35/J35-1),"-",($H35/J35-1)) -> -3.0303841 | T35: =IF(ISERROR($L35/N35-1),"-",($L35/N35-1)) -> -0.28136316 | U35: =IF(ISERROR($D35/$D$15),"-",($D35/$D$15)) -> -1.5224067e-06 | Y35: =IF(ISERROR($H35/$H$15),"-",($H35/$H$15)) -> 5.8232957e-05 | AC35: =IF(ISERROR($L35/$L$15),"-",($L35/$L$15)) -> 6.1790054e-05 | AE35: =IF(ISERROR(N35/N$15),"-",(N35/N$15)) -> 8.9746864e-05 | AG35: =-W35*AE35 -> 0
B36: Despesas Financeiras | D36: ='03- BD x RE 2026'!D69/1000 -> -12.151528 | F36: ='03- BD x RE 2026'!E69/1000 -> -2.30552 | H36: ='03- BD x RE 2026'!G69/1000 -> -18.65218 | J36: ='03- BD x RE 2026'!H69/1000 -> -0.77606 | L36: ='03- BD x RE 2026'!J69/1000 -> -18.797602 | N36: ='03- BD x RE 2026'!K69/1000 -> -0.451 | P36: =IF(ISERROR($F36/D36-1),"-",($F36/D36-1)) -> -0.81026913 | R36: =IF(ISERROR($H36/J36-1),"-",($H36/J36-1)) -> 23.034456 | T36: =IF(ISERROR($L36/N36-1),"-",($L36/N36-1)) -> 40.679826 | U36: =IF(ISERROR($D36/$D$15),"-",($D36/$D$15)) -> -0.0075798592 | W36: =IF(ISERROR(F36/F$15),"-",(F36/F$15)) -> -0.0017220001 | Y36: =IF(ISERROR($H36/$H$15),"-",($H36/$H$15)) -> -0.0075798592 | AA36: =IF(ISERROR(J36/J$15),"-",(J36/J$15)) -> -0.00051492666 | AC36: =IF(ISERROR($L36/$L$15),"-",($L36/$L$15)) -> -0.007555386 | AE36: =IF(ISERROR(N36/N$15),"-",(N36/N$15)) -> -0.00018920863 | AG36: =-W36*AE36 -> -3.2581728e-07
B37: Despesas Pré-Operacionais | H37: ='03- BD x RE 2026'!G70/1000 -> 0 | J37: ='[2]9 1 DRE R23'!P68/1000 -> 0 | L37: ='03- BD x RE 2026'!J70/1000 -> 0 | N37: ='03- BD x RE 2026'!K70/1000 -> 0 | P37: =IF(ISERROR(#REF!/D37-1),"-",(#REF!/D37-1)) -> - | R37: =IF(ISERROR($H37/J37-1),"-",($H37/J37-1)) -> - | T37: =IF(ISERROR($H37/K37-1),"-",($H37/K37-1)) -> - | U37: =IF(ISERROR($D37/$D$15),"-",($D37/$D$15)) -> 0 | W37: =IF(ISERROR(F37/F$15),"-",(F37/F$15)) -> 0 | Y37: =IF(ISERROR($H37/$H$15),"-",($H37/$H$15)) -> 0 | AA37: =IF(ISERROR(J37/J$15),"-",(J37/J$15)) -> 0 | AC37: =IF(ISERROR($L37/$L$15),"-",($L37/$L$15)) -> 0 | AE37: =IF(ISERROR(N37/N$15),"-",(N37/N$15)) -> 0 | AG37: =-W37*AE37 -> 0
B38: IRPJ/CSLL | H38: ='03- BD x RE 2026'!G71/1000 -> 0 | L38: ='03- BD x RE 2026'!J71/1000 -> 0 | N38: ='03- BD x RE 2026'!K71/1000 -> 0 | P38: =IF(ISERROR($F38/D38-1),"-",($F38/D38-1)) -> - | R38: =IF(ISERROR($H38/J38-1),"-",($H38/J38-1)) -> - | T38: =IF(ISERROR($H38/K38-1),"-",($H38/K38-1)) -> - | U38: =IF(ISERROR($D38/$D$15),"-",($D38/$D$15)) -> 0 | W38: =IF(ISERROR(F38/F$15),"-",(F38/F$15)) -> 0 | Y38: =IF(ISERROR($H38/$H$15),"-",($H38/$H$15)) -> 0 | AA38: =IF(ISERROR(J38/J$15),"-",(J38/J$15)) -> 0 | AC38: =IF(ISERROR($L38/$L$15),"-",($L38/$L$15)) -> 0 | AE38: =IF(ISERROR(N38/N$15),"-",(N38/N$15)) -> 0 | AG38: =-W38*AE38 -> 0
R39: =IF(ISERROR($H39/J39-1),"-",($H39/J39-1)) -> - | T39: =IF(ISERROR($H39/K39-1),"-",($H39/K39-1)) -> -
B40: RESULTADO OPERACIONAL | D40: =D34+D36+D37+D38 -> -16.06417 | F40: =F34+F36+F37+F38 -> -246.97582 | H40: =H34+H36+H37+H38 -> 333.96685 | J40: =J34+J36+J37+J38 -> -107.14357 | L40: =L34+L36+L37+L38 -> 363.68365 | N40: =N34+N36+N37+N38 -> 509.45543 | P40: =IF(ISERROR($F40/D40-1),"-",($F40/D40-1)) -> 14.374328 | R40: =IF(ISERROR($H40/J40-1),"-",($H40/J40-1)) -> -4.1170031 | T40: =IF(ISERROR($H40/K40-1),"-",($H40/K40-1)) -> - | U40: =IF(ISERROR($D40/$D$15),"-",($D40/$D$15)) -> -0.010020481 | W40: =IF(ISERROR(F40/F$15),"-",(F40/F$15)) -> -0.18446701 | Y40: =IF(ISERROR($H40/$H$15),"-",($H40/$H$15)) -> 0.13571721 | AA40: =IF(ISERROR(J40/J$15),"-",(J40/J$15)) -> -0.071091259 | AC40: =IF(ISERROR($L40/$L$15),"-",($L40/$L$15)) -> 0.14617664 | AE40: =IF(ISERROR(N40/N$15),"-",(N40/N$15)) -> 0.21373251 | AG40: =-W40*AE40 -> 0.039426598
B41: ='[2]2 DRE '!A70 -> Margem líquida | D41: =IF(ISERROR(D40/D15),0,(D40/D15)) -> -0.010020481 | F41: =IF(ISERROR(F40/F15),0,(F40/F15)) -> -0.18446701 | H41: =IF(ISERROR(H40/H15),0,(H40/H15)) -> 0.13571721 | J41: =IF(ISERROR(J40/J15),0,(J40/J15)) -> -0.071091259 | L41: =IF(ISERROR(L40/L15),0,(L40/L15)) -> 0.14617664 | N41: =IF(ISERROR(N40/N15),0,(N40/N15)) -> 0.21373251

Sheet 03- BD x RE 2026
A1: BD(2026)
C5: 2026 | D5: JAN | G5: FEV | J5: MAR | M5: ABR | P5: MAI | S5: JUN | V5: JUL | Y5: AGO | AB5: SET | AE5: OUT | AH5: NOV | AK5: DEZ | AN5: 2026 ACUM. | AQ5: 2026 MÉDIA ANUAL | AT5: 2026 PART% | AV5: JAN | AW5: FEV | AX5: MAR | AY5: ABR | AZ5: MAI | BA5: JUN | BB5: JUL | BC5: AGO | BD5: SET | BE5: OUT | BF5: NOV | BG5: DEZ
D6: PROJETADO | E6: REALIZADO | G6: PROJETADO | H6: REALIZADO | J6: PROJETADO | K6: REALIZADO | M6: PROJETADO | N6: REALIZADO | P6: PROJETADO | Q6: REALIZADO | S6: PROJETADO | T6: REALIZADO | V6: PROJETADO | W6: REALIZADO | Y6: PROJETADO | Z6: REALIZADO | AB6: PROJETADO | AC6: REALIZADO | AE6: PROJETADO | AF6: REALIZADO | AH6: PROJETADO | AI6: REALIZADO | AK6: PROJETADO | AL6: REALIZADO | AN6: PROJETADO | AO6: REALIZADO | AQ6: PROJETADO | AR6: REALIZADO
A7: CLIENTES | C7: =SUM(D7,G7,J7,M7,P7,S7,V7,Y7,AB7,AE7,AH7,AK7) -> 94390.712 | D7: ='04 -Base Orçado 2026'!E7 -> 5786.4418 | E7: ='Base Realizado'!D7 -> 4761 | G7: ='04 -Base Orçado 2026'!F7 -> 7860.1684 | H7: ='Base Realizado'!F7 -> 4661 | J7: ='04 -Base Orçado 2026'!G7 -> 7921.4504 | K7: ='Base Realizado'!H7 -> 6592 | M7: ='04 -Base Orçado 2026'!H7 -> 8127.4243 | N7: ='Base Realizado'!K7 -> 0 | P7: ='04 -Base Orçado 2026'!I7 -> 9134.876 | S7: ='04 -Base Orçado 2026'!J7 -> 7745.6024 | V7: ='04 -Base Orçado 2026'!K7 -> 7474.4325 | Y7: ='04 -Base Orçado 2026'!L7 -> 7645.5461 | AB7: ='04 -Base Orçado 2026'!M7 -> 7551.431 | AE7: ='04 -Base Orçado 2026'!N7 -> 7336.2258 | AH7: ='04 -Base Orçado 2026'!O7 -> 8672.2369 | AK7: ='03- BD x RE 2026'!P7 -> 9134.876 | AN7: =SUM(D7,G7,J7,M7,P7,S7,V7,Y7,AB7,AE7,AH7,AK7) -> 94390.712 | AO7: =SUM(E7,H7,K7,N7,Q7,T7,W7,Z7,AC7,AF7,AI7,AL7) -> 16014 | AQ7: =AN7/12 -> 7865.8926
A8: Ticket Médio - R$M | C8: =SUM(D8,G8,J8,M8,P8,S8,V8,Y8,AB8,AE8,AH8,AK8) -> 3600 | D8: ='04 -Base Orçado 2026'!E8 -> 300 | E8: ='Base Realizado'!D8 -> 289.76034 | G8: ='04 -Base Orçado 2026'!F8 -> 300 | H8: ='Base Realizado'!F8 -> 312.20426 | J8: ='04 -Base Orçado 2026'!G8 -> 300 | K8: ='Base Realizado'!H8 -> 317.16391 | M8: ='04 -Base Orçado 2026'!H8 -> 300 | N8: ='Base Realizado'!K8 -> 0 | P8: ='04 -Base Orçado 2026'!I8 -> 300 | S8: ='04 -Base Orçado 2026'!J8 -> 300 | V8: ='04 -Base Orçado 2026'!K8 -> 300 | Y8: ='04 -Base Orçado 2026'!L8 -> 300 | AB8: ='04 -Base Orçado 2026'!M8 -> 300 | AE8: ='04 -Base Orçado 2026'!N8 -> 300 | AH8: ='04 -Base Orçado 2026'!O8 -> 300 | AK8: ='04 -Base Orçado 2026'!P8 -> 300 | AN8: =IF(ISERROR(AN10/AN7),"0",(AN10/AN7)) -> 326.05316 | AO8: =IF(ISERROR(AO10/AO7),"0",(AO10/AO7)) -> 478.25187 | AQ8: =IF(ISERROR(AQ10/AQ7),"0",(AQ10/AQ7)) -> 326.05316
A10: Faturamento Bruto | C10: =SUM(D10,G10,J10,M10,P10,S10,V10,Y10,AB10,AE10,AH10,AK10) -> 30776390 | D10: =SUM(D11:D17)-D11 -> 1735932.5 | E10: =SUM(E11:E17)-E11 -> 1390349 | G10: =SUM(G11:G17) -> 2664597.1 | H10: =SUM(H11:H17)-H11 -> 1528554.1 | J10: =SUM(J11:J17) -> 2693404.7 | K10: =SUM(K11:K17)-K11 -> 2443536.8 | M10: =SUM(M11:M17) -> 2755196.8 | N10: =SUM(N11:N17)-N11 -> 2296285.6 | P10: =SUM(P11:P17) -> 3096723 | S10: =SUM(S11:S17) -> 2625759.2 | V10: =SUM(V11:V17) -> 2533832.6 | Y10: =SUM(Y11:Y17) -> 2591840.1 | AB10: =SUM(AB11:AB17) -> 2559935.1 | AE10: =SUM(AE11:AE17) -> 2486980.5 | AH10: =SUM(AH11:AH17) -> 2939888.3 | AK10: =SUM(AK11:AK17) -> 2092300.1 | AN10: =SUM(D10,G10,J10,M10,P10,S10,V10,Y10,AB10,AE10,AH10,AK10) -> 30776390 | AO10: =SUM(E10,H10,K10,N10,Q10,T10,W10,Z10,AC10,AF10,AI10,AL10) -> 7658725.4 | AQ10: =AN10/12 -> 2564699.2 | AR10: =AQ10/$AT$12 -> 641174.79
A11: Gorjetas Recebidas | C11: =SUM(D11,G11,J11,M11,P11,S11,V11,Y11,AB11,AE11,AH11,AK11) -> 3573717.7 | D11: ='04 -Base Orçado 2026'!E13 -> 225671.23 | E11: ='Base Realizado'!D12 -> 110797.62 | G11: ='04 -Base Orçado 2026'!F13 -> 306546.57 | H11: ='Base Realizado'!F12 -> 198712 | J11: ='04 -Base Orçado 2026'!H13 -> 316969.55 | K11: ='Base Realizado'!H12 -> 116627.58 | M11: ='04 -Base Orçado 2026'!H13 -> 316969.55 | N11: ='Base Realizado'!N12 -> 0 | P11: ='04 -Base Orçado 2026'!I13 -> 356260.16 | S11: ='04 -Base Orçado 2026'!J13 -> 302078.5 | V11: ='04 -Base Orçado 2026'!K13 -> 291502.87 | Y11: ='04 -Base Orçado 2026'!L13 -> 298176.3 | AB11: ='04 -Base Orçado 2026'!M13 -> 294505.81 | AE11: ='04 -Base Orçado 2026'!N13 -> 286112.81 | AH11: ='04 -Base Orçado 2026'!O13 -> 338217.24 | AK11: ='04 -Base Orçado 2026'!P13 -> 240707.09
A12: Dinheiro | C12: =SUM(D12,G12,J12,M12,P12,S12,V12,Y12,AB12,AE12,AH12,AK12) -> 548566.87 | D12: ='04 -Base Orçado 2026'!E14 -> 34718.651 | E12: ='Base Realizado'!D13 -> 191219.93 | G12: ='04 -Base Orçado 2026'!F14 -> 47161.01 | H12: ='Base Realizado'!F13 -> 232968.95 | J12: ='04 -Base Orçado 2026'!G14 -> 47528.702 | K12: ='Base Realizado'!H13 -> 339893.43 | M12: ='04 -Base Orçado 2026'!H14 -> 48764.546 | N12: ='Base Realizado'!K12 -> 0 | P12: ='04 -Base Orçado 2026'!I14 -> 54809.256 | S12: ='04 -Base Orçado 2026'!J14 -> 46473.615 | V12: ='04 -Base Orçado 2026'!K14 -> 44846.595 | Y12: ='04 -Base Orçado 2026'!L14 -> 45873.276 | AB12: ='04 -Base Orçado 2026'!M14 -> 45308.586 | AE12: ='04 -Base Orçado 2026'!N14 -> 44017.355 | AH12: ='04 -Base Orçado 2026'!O14 -> 52033.422 | AK12: ='04 -Base Orçado 2026'!P14 -> 37031.86 | AN12: =SUM(D12,G12,J12,M12,P12,S12,V12,Y12,AB12,AE12,AH12,AK12) -> 548566.87 | AO12: =SUM(E12,H12,K12,N12,Q12,T12,W12,Z12,AC12,AF12,AI12,AL12) -> 764082.31 | AQ12: =AVERAGE(D12,G12,J12) -> 43136.121 | AR12: =AVERAGE(E12,H12,K12) -> 254694.1 | AT12: =COUNTA(E12,H12,K12,N12,Q12,T12,W12,Z12,AC12,AF12,AI12,AL12) -> 4
A13: Cartão de Débito | C13: =SUM(D13,G13,J13,M13,P13,S13,V13,Y13,AB13,AE13,AH13,AK13) -> 1919984.1 | D13: ='04 -Base Orçado 2026'!E15 -> 121515.28 | E13: ='Base Realizado'!D14 -> 213780.01 | G13: ='04 -Base Orçado 2026'!F15 -> 165063.54 | H13: ='Base Realizado'!F14 -> 988071.98 | J13: ='04 -Base Orçado 2026'!G15 -> 166350.46 | K13: ='Base Realizado'!H14 -> 289846.25 | M13: ='04 -Base Orçado 2026'!H15 -> 170675.91 | N13: ='Base Realizado'!K13 -> 299094.7 | P13: ='04 -Base Orçado 2026'!I15 -> 191832.4 | S13: ='04 -Base Orçado 2026'!J15 -> 162657.65 | V13: ='04 -Base Orçado 2026'!K15 -> 156963.08 | Y13: ='04 -Base Orçado 2026'!L15 -> 160556.47 | AB13: ='04 -Base Orçado 2026'!M15 -> 158580.05 | AE13: ='04 -Base Orçado 2026'!N15 -> 154060.74 | AH13: ='04 -Base Orçado 2026'!O15 -> 182116.98 | AK13: ='04 -Base Orçado 2026'!P15 -> 129611.51 | AN13: =SUM(D13,G13,J13,M13,P13,S13,V13,Y13,AB13,AE13,AH13,AK13) -> 1919984.1 | AO13: =SUM(E13,H13,K13,N13,Q13,T13,W13,Z13,AC13,AF13,AI13,AL13) -> 1790792.9 | AQ13: =AVERAGE(D13,G13,J13) -> 150976.42 | AR13: =AVERAGE(E13,H13,K13) -> 497232.75 | AT13: =COUNTA(E13,H13,K13,N13,Q13,T13,W13,Z13,AC13,AF13,AI13,AL13) -> 4
A14: Cartão de Crédito | C14: =SUM(D14,G14,J14,M14,P14,S14,V14,Y14,AB14,AE14,AH14,AK14) -> 17992993 | D14: ='04 -Base Orçado 2026'!E16 -> 1138771.7 | E14: ='Base Realizado'!D15 -> 963659.96 | G14: ='04 -Base Orçado 2026'!F16 -> 1546881.1 | H14: ='Base Realizado'!F15 -> 223553.48 | J14: ='04 -Base Orçado 2026'!G16 -> 1558941.4 | K14: ='Base Realizado'!H15 -> 1455192.1 | M14: ='04 -Base Orçado 2026'!H16 -> 1599477.1 | N14: ='Base Realizado'!K14 -> 313558.29 | P14: ='04 -Base Orçado 2026'!I16 -> 1797743.6 | S14: ='04 -Base Orçado 2026'!J16 -> 1524334.6 | V14: ='04 -Base Orçado 2026'!K16 -> 1470968.3 | Y14: ='04 -Base Orçado 2026'!L16 -> 1504643.5 | AB14: ='04 -Base Orçado 2026'!M16 -> 1486121.6 | AE14: ='04 -Base Orçado 2026'!N16 -> 1443769.2 | AH14: ='04 -Base Orçado 2026'!O16 -> 1706696.2 | AK14: ='04 -Base Orçado 2026'!P16 -> 1214645 | AN14: =SUM(D14,G14,J14,M14,P14,S14,V14,Y14,AB14,AE14,AH14,AK14) -> 17992993 | AO14: =SUM(E14,H14,K14,N14,Q14,T14,W14,Z14,AC14,AF14,AI14,AL14) -> 2955963.8 | AQ14: =AVERAGE(D14,G14,J14) -> 1414864.8 | AR14: =AVERAGE(E14,H14,K14) -> 880801.84 | AT14: =COUNTA(E14,H14,K14,N14,Q14,T14,W14,Z14,AC14,AF14,AI14,AL14) -> 4
A15: Evento Faturado | C15: =SUM(D15,G15,J15,M15,P15,S15,V15,Y15,AB15,AE15,AH15,AK15) -> 2742834.4 | D15: ='04 -Base Orçado 2026'!E17 -> 173593.25 | E15: ='Base Realizado'!D16 -> 10800 | G15: ='04 -Base Orçado 2026'!F17 -> 235805.05 | H15: ='Base Realizado'!F16 -> 73370 | J15: ='04 -Base Orçado 2026'!G17 -> 237643.51 | K15: ='Base Realizado'!H16 -> 352792.26 | M15: ='04 -Base Orçado 2026'!H17 -> 243822.73 | N15: ='Base Realizado'!K15 -> 1524543.3 | P15: ='04 -Base Orçado 2026'!I17 -> 274046.28 | S15: ='04 -Base Orçado 2026'!J17 -> 232368.07 | V15: ='04 -Base Orçado 2026'!K17 -> 224232.98 | Y15: ='04 -Base Orçado 2026'!L17 -> 229366.38 | AB15: ='04 -Base Orçado 2026'!M17 -> 226542.93 | AE15: ='04 -Base Orçado 2026'!N17 -> 220086.77 | AH15: ='04 -Base Orçado 2026'!O17 -> 260167.11 | AK15: ='04 -Base Orçado 2026'!P17 -> 185159.3 | AN15: =SUM(D15,G15,J15,M15,P15,S15,V15,Y15,AB15,AE15,AH15,AK15) -> 2742834.4 | AO15: =SUM(E15,H15,K15,N15,Q15,T15,W15,Z15,AC15,AF15,AI15,AL15) -> 1961505.6 | AQ15: =AVERAGE(D15,G15,J15) -> 215680.61 | AR15: =AVERAGE(E15,H15,K15) -> 145654.09 | AT15: =COUNTA(E15,H15,K15,N15,Q15,T15,W15,Z15,AC15,AF15,AI15,AL15) -> 4
A16: Delivery | C16: =SUM(D16,G16,J16,M16,P16,S16,V16,Y16,AB16,AE16,AH16,AK16) -> 4114251.5 | D16: ='04 -Base Orçado 2026'!E18 -> 260389.88 | G16: ='04 -Base Orçado 2026'!F18 -> 353707.58 | H16: ='Base Realizado'!F17 -> 0 | J16: ='04 -Base Orçado 2026'!G18 -> 356465.27 | K16: ='Base Realizado'!H17 -> 0 | M16: ='04 -Base Orçado 2026'!H18 -> 365734.09 | N16: ='Base Realizado'!K16 -> 159089.31 | P16: ='04 -Base Orçado 2026'!I18 -> 411069.42 | S16: ='04 -Base Orçado 2026'!J18 -> 348552.11 | V16: ='04 -Base Orçado 2026'!K18 -> 336349.46 | Y16: ='04 -Base Orçado 2026'!L18 -> 344049.57 | AB16: ='04 -Base Orçado 2026'!M18 -> 339814.4 | AE16: ='04 -Base Orçado 2026'!N18 -> 330130.16 | AH16: ='04 -Base Orçado 2026'!O18 -> 390250.66 | AK16: ='04 -Base Orçado 2026'!P18 -> 277738.95 | AN16: =SUM(D16,G16,J16,M16,P16,S16,V16,Y16,AB16,AE16,AH16,AK16) -> 4114251.5 | AO16: =SUM(E16,H16,K16,N16,Q16,T16,W16,Z16,AC16,AF16,AI16,AL16) -> 159089.31 | AQ16: =AVERAGE(D16,G16,J16) -> 323520.91 | AR16: =AVERAGE(E16,H16,K16) -> 0 | AT16: =COUNTA(E16,H16,K16,N16,Q16,T16,W16,Z16,AC16,AF16,AI16,AL16) -> 3
A17: Voucher | C17: =SUM(D17,G17,J17,M17,P17,S17,V17,Y17,AB17,AE17,AH17,AK17) -> 109713.37 | D17: ='04 -Base Orçado 2026'!E19 -> 6943.7302 | E17: ='Base Realizado'!D18 -> 10889.07 | G17: ='04 -Base Orçado 2026'!F19 -> 9432.2021 | H17: ='Base Realizado'!F18 -> 10589.65 | J17: ='04 -Base Orçado 2026'!G19 -> 9505.7404 | K17: ='Base Realizado'!H18 -> 5812.74 | M17: ='04 -Base Orçado 2026'!H19 -> 9752.9091 | N17: ='Base Realizado'!K17 -> 0 | P17: ='04 -Base Orçado 2026'!I19 -> 10961.851 | S17: ='04 -Base Orçado 2026'!J19 -> 9294.7229 | V17: ='04 -Base Orçado 2026'!K19 -> 8969.319 | Y17: ='04 -Base Orçado 2026'!L19 -> 9174.6553 | AB17: ='04 -Base Orçado 2026'!M19 -> 9061.7172 | AE17: ='04 -Base Orçado 2026'!N19 -> 8803.471 | AH17: ='04 -Base Orçado 2026'!O19 -> 10406.684 | AK17: ='04 -Base Orçado 2026'!P19 -> 7406.3719 | AN17: =SUM(D17,G17,J17,M17,P17,S17,V17,Y17,AB17,AE17,AH17,AK17) -> 109713.37 | AQ17: =AVERAGE(D17,G17,J17) -> 8627.2242 | AR17: =AVERAGE(E17,H17,K17) -> 9097.1533 | AT17: =COUNTA(E17,H17,K17,N17,Q17,T17,W17,Z17,AC17,AF17,AI17,AL17) -> 4
A19: Impostos sobre Vendas | C19: =SUM(D19,G19,J19,M19,P19,S19,V19,Y19,AB19,AE19,AH19,AK19) -> -2353779.3 | D19: =SUM(D20:D23) -> -132798.84 | E19: =SUM(E20:E23) -> -51487.25 | G19: =SUM(G20:G23) -> -203841.68 | H19: =SUM(H20:H23) -> -21426.81 | J19: =SUM(J20:J23) -> -205430.93 | K19: =SUM(K20:K23) -> -59924.54 | M19: =SUM(M20:M23) -> -210772.56 | N19: =SUM(N20:N23) -> 0 | P19: =SUM(P20:P23) -> -236899.31 | S19: =SUM(S20:S23) -> -200870.58 | V19: =SUM(V20:V23) -> -193838.2 | Y19: =SUM(Y20:Y23) -> -198275.77 | AB19: =SUM(AB20:AB23) -> -195835.04 | AE19: =SUM(AE20:AE23) -> -190254.01 | AH19: =SUM(AH20:AH23) -> -224901.46 | AK19: =SUM(AK20:AK23) -> -160060.96 | AN19: =SUM(D19,G19,J19,M19,P19,S19,V19,Y19,AB19,AE19,AH19,AK19) -> -2353779.3 | AO19: =SUM(E19,H19,K19,N19,Q19,T19,W19,Z19,AC19,AF19,AI19,AL19) -> -132838.6 | AQ19: =AVERAGE(D19,G19,J19) -> -180690.48 | AR19: =AVERAGE(E19,H19,K19) -> -44279.533 | AT19: =SUM(AT20:AT23) -> -0.082813621 | AV19: =SUM(AV20:AV23) -> -0.082837033 | AW19: =SUM(AW20:AW23) -> -0.082837033 | AX19: =SUM(AX20:AX23) -> -0.082569575 | AY19: =SUM(AY20:AY23) -> -0.082837033 | AZ19: =SUM(AZ20:AZ23) -> -0.082837033 | BA19: =SUM(BA20:BA23) -> -0.082837033 | BB19: =SUM(BB20:BB23) -> -0.082837033 | BC19: =SUM(BC20:BC23) -> -0.082837033 | ... BG19: =SUM(BG20:BG23) -> -0.082837033
A20: ICMS | C20: =SUM(D20,G20,J20,M20,P20,S20,V20,Y20,AB20,AE20,AH20,AK20) -> -1230734.3 | D20: ='04 -Base Orçado 2026'!E22 -> -69437.302 | E20: ='Base Realizado'!D21 -> -11603.07 | G20: ='04 -Base Orçado 2026'!F22 -> -106583.88 | H20: ='B. Despesa'!H2388 -> -1056 | J20: ='04 -Base Orçado 2026'!G22 -> -107414.87 | K20: ='Base Realizado'!H21 -> -37427.25 | M20: ='04 -Base Orçado 2026'!H22 -> -110207.87 | N20: ='Base Realizado'!K20 -> 0 | P20: ='04 -Base Orçado 2026'!I22 -> -123868.92 | S20: ='04 -Base Orçado 2026'!J22 -> -105030.37 | V20: ='04 -Base Orçado 2026'!K22 -> -101353.3 | Y20: ='04 -Base Orçado 2026'!L22 -> -103673.6 | AB20: ='04 -Base Orçado 2026'!M22 -> -102397.4 | AE20: ='04 -Base Orçado 2026'!N22 -> -99479.222 | AH20: ='04 -Base Orçado 2026'!O22 -> -117595.53 | AK20: ='04 -Base Orçado 2026'!P22 -> -83692.003 | AN20: =SUM(D20,G20,J20,M20,P20,S20,V20,Y20,AB20,AE20,AH20,AK20) -> -1230734.3 | AO20: =SUM(E20,H20,K20,N20,Q20,T20,W20,Z20,AC20,AF20,AI20,AL20) -> -50086.32 | AQ20: =AVERAGE(D20,G20,J20) -> -94478.684 | AR20: =AVERAGE(E20,H20,K20) -> -16695.44 | AT20: =IF(ISERROR(C20/C$24),0,(C20/C$24)) -> -0.04330124 | AV20: =IF(ISERROR(D20/D$24),0,(D20/D$24)) -> -0.043313481 | AW20: =IF(ISERROR(G20/G$24),0,(G20/G$24)) -> -0.043313481 | AX20: =IF(ISERROR(J20/J$24),0,(J20/J$24)) -> -0.043173634 | AY20: =IF(ISERROR(M20/M$24),0,(M20/M$24)) -> -0.043313481 | AZ20: =IF(ISERROR(P20/P$24),0,(P20/P$24)) -> -0.043313481 | BA20: =IF(ISERROR(S20/S$24),0,(S20/S$24)) -> -0.043313481 | BB20: =IF(ISERROR(V20/V$24),0,(V20/V$24)) -> -0.043313481 | BC20: =IF(ISERROR(Y20/Y$24),0,(Y20/Y$24)) -> -0.043313481 | BD20: =IF(ISERROR(AB20/AB$24),0,(AB20/AB$24)) -> -0.043313481 | BE20: =IF(ISERROR(AE20/AE$24),0,(AE20/AE$24)) -> -0.043313481 | BF20: =IF(ISERROR(AH20/AH$24),0,(AH20/AH$24)) -> -0.043313481 | BG20: =IF(ISERROR(AK20/AK$24),0,(AK20/AK$24)) -> -0.043313481
A21: COFINS | C21: =SUM(D21,G21,J21,M21,P21,S21,V21,Y21,AB21,AE21,AH21,AK21) -> -923050.71 | D21: ='04 -Base Orçado 2026'!E23 -> -52077.976 | E21: ='Base Realizado'!D22 -> -18007.73 | G21: ='04 -Base Orçado 2026'!F23 -> -79937.913 | H21: ='B. Despesa'!H2389 -> -15493.73 | J21: ='04 -Base Orçado 2026'!G23 -> -80561.15 | K21: ='Base Realizado'!H22 -> -18490.92 | M21: ='04 -Base Orçado 2026'!H23 -> -82655.905 | N21: ='Base Realizado'!K21 -> 0 | P21: ='04 -Base Orçado 2026'!I23 -> -92901.689 | S21: ='04 -Base Orçado 2026'!J23 -> -78772.777 | V21: ='04 -Base Orçado 2026'!K23 -> -76014.979 | Y21: ='04 -Base Orçado 2026'!L23 -> -77755.204 | AB21: ='04 -Base Orçado 2026'!M23 -> -76798.054 | AE21: ='04 -Base Orçado 2026'!N23 -> -74609.416 | AH21: ='04 -Base Orçado 2026'!O23 -> -88196.649 | AK21: ='04 -Base Orçado 2026'!P23 -> -62769.002 | AN21: =SUM(D21,G21,J21,M21,P21,S21,V21,Y21,AB21,AE21,AH21,AK21) -> -923050.71 | AO21: =SUM(E21,H21,K21,N21,Q21,T21,W21,Z21,AC21,AF21,AI21,AL21) -> -51992.38 | AQ21: =AVERAGE(D21,G21,J21) -> -70859.013 | AR21: =AVERAGE(E21,H21,K21) -> -17330.793 | AT21: =IF(ISERROR(C21/C$24),0,(C21/C$24)) -> -0.03247593 | AV21: =IF(ISERROR(D21/D$24),0,(D21/D$24)) -> -0.032485111 | AW21: =IF(ISERROR(G21/G$24),0,(G21/G$24)) -> -0.032485111 | AX21: =IF(ISERROR(J21/J$24),0,(J21/J$24)) -> -0.032380226 | AY21: =IF(ISERROR(M21/M$24),0,(M21/M$24)) -> -0.032485111 | AZ21: =IF(ISERROR(P21/P$24),0,(P21/P$24)) -> -0.032485111 | BA21: =IF(ISERROR(S21/S$24),0,(S21/S$24)) -> -0.032485111 | BB21: =IF(ISERROR(V21/V$24),0,(V21/V$24)) -> -0.032485111 | BC21: =IF(ISERROR(Y21/Y$24),0,(Y21/Y$24)) -> -0.032485111 | BD21: =IF(ISERROR(AB21/AB$24),0,(AB21/AB$24)) -> -0.032485111 | BE21: =IF(ISERROR(AE21/AE$24),0,(AE21/AE$24)) -> -0.032485111 | BF21: =IF(ISERROR(AH21/AH$24),0,(AH21/AH$24)) -> -0.032485111 | BG21: =IF(ISERROR(AK21/AK$24),0,(AK21/AK$24)) -> -0.032485111
A22: PIS | C22: =SUM(D22,G22,J22,M22,P22,S22,V22,Y22,AB22,AE22,AH22,AK22) -> -199994.32 | D22: ='04 -Base Orçado 2026'!E24 -> -11283.562 | E22: ='Base Realizado'!D23 -> -21876.45 | G22: ='04 -Base Orçado 2026'!F24 -> -17319.881 | H22: ='B. Despesa'!H2390 -> -4877.08 | J22: ='04 -Base Orçado 2026'!G24 -> -17454.916 | K22: ='Base Realizado'!H23 -> -4006.37 | M22: ='04 -Base Orçado 2026'!H24 -> -17908.779 | N22: ='Base Realizado'!K22 -> 0 | P22: ='04 -Base Orçado 2026'!I24 -> -20128.699 | S22: ='04 -Base Orçado 2026'!J24 -> -17067.435 | V22: ='04 -Base Orçado 2026'!K24 -> -16469.912 | Y22: ='04 -Base Orçado 2026'!L24 -> -16846.961 | AB22: ='04 -Base Orçado 2026'!M24 -> -16639.578 | AE22: ='04 -Base Orçado 2026'!N24 -> -16165.374 | AH22: ='04 -Base Orçado 2026'!O24 -> -19109.274 | AK22: ='04 -Base Orçado 2026'!P24 -> -13599.95 | AN22: =SUM(D22,G22,J22,M22,P22,S22,V22,Y22,AB22,AE22,AH22,AK22) -> -199994.32 | AO22: =SUM(E22,H22,K22,N22,Q22,T22,W22,Z22,AC22,AF22,AI22,AL22) -> -30759.9 | AQ22: =AVERAGE(D22,G22,J22) -> -15352.786 | AR22: =AVERAGE(E22,H22,K22) -> -10253.3 | AT22: =IF(ISERROR(C22/C$24),0,(C22/C$24)) -> -0.0070364515 | AV22: =IF(ISERROR(D22/D$24),0,(D22/D$24)) -> -0.0070384407 | AW22: =IF(ISERROR(G22/G$24),0,(G22/G$24)) -> -0.0070384407 | AX22: =IF(ISERROR(J22/J$24),0,(J22/J$24)) -> -0.0070157155 | AY22: =IF(ISERROR(M22/M$24),0,(M22/M$24)) -> -0.0070384407 | AZ22: =IF(ISERROR(P22/P$24),0,(P22/P$24)) -> -0.0070384407 | BA22: =IF(ISERROR(S22/S$24),0,(S22/S$24)) -> -0.0070384407 | BB22: =IF(ISERROR(V22/V$24),0,(V22/V$24)) -> -0.0070384407 | BC22: =IF(ISERROR(Y22/Y$24),0,(Y22/Y$24)) -> -0.0070384407 | BD22: =IF(ISERROR(AB22/AB$24),0,(AB22/AB$24)) -> -0.0070384407 | BE22: =IF(ISERROR(AE22/AE$24),0,(AE22/AE$24)) -> -0.0070384407 | BF22: =IF(ISERROR(AH22/AH$24),0,(AH22/AH$24)) -> -0.0070384407 | BG22: =IF(ISERROR(AK22/AK$24),0,(AK22/AK$24)) -> -0.0070384407
C23: =SUM(D23,G23,J23,M23,P23,S23,V23,Y23,AB23,AE23,AH23,AK23) -> 0
A24: Receita Líquida | C24: =SUM(D24,G24,J24,M24,P24,S24,V24,Y24,AB24,AE24,AH24,AK24) -> 28422611 | D24: =D10+D19 -> 1603133.7 | E24: =E10+E19 -> 1338861.7 | G24: =G10+G19 -> 2460755.4 | H24: =H10+H19 -> 1507127.3 | J24: =J10+J19 -> 2487973.7 | K24: =K10+K19 -> 2383612.2 | M24: =M10+M19 -> 2544424.3 | N24: =N10+N19 -> 2296285.6 | P24: =P10+P19 -> 2859823.6 | S24: =S10+S19 -> 2424888.6 | V24: =V10+V19 -> 2339994.4 | Y24: =Y10+Y19 -> 2393564.4 | AB24: =AB10+AB19 -> 2364100.1 | AE24: =AE10+AE19 -> 2296726.5 | AH24: =AH10+AH19 -> 2714986.9 | AK24: =AK10+AK19 -> 1932239.1 | AN24: =SUM(D24,G24,J24,M24,P24,S24,V24,Y24,AB24,AE24,AH24,AK24) -> 28422611 | AO24: =SUM(E24,H24,K24,N24,Q24,T24,W24,Z24,AC24,AF24,AI24,AL24) -> 7525886.8 | AQ24: =AVERAGE(D24,G24,J24) -> 2183954.3 | AR24: =AVERAGE(E24,H24,K24) -> 1743200.4 | AT24: =C24/C10 -> 0.92351997
C25: =SUM(D25,G25,J25,M25,P25,S25,V25,Y25,AB25,AE25,AH25,AK25) -> 0 | AN25: =SUM(D25:AK25) -> 0
A26: CUSTOS/DESPESAS | C26: =SUM(D26,G26,J26,M26,P26,S26,V26,Y26,AB26,AE26,AH26,AK26) -> -21293530 | D26: =SUM(,D28,D44,D49,D50,D51,D52) -> -1368519.3 | E26: =SUM(,E28,E44,E49,E50,E51,E52) -> -1331701.3 | G26: =SUM(,G28,G44,G49,G50,G51,G52) -> -1822211.2 | H26: =SUM(,H28,H44,H49,H50,H51,H52) -> -1408175.9 | J26: =SUM(J29:J52) -> -1821906.4 | K26: =SUM(,K28,K44,K49,K50,K51,K52) -> -1640580.2 | M26: =SUM(M29:M52) -> -1852795.8 | N26: =SUM(,N28,N44,N49,N50,N51,N52) -> -1890226.7 | P26: =SUM(P29:P52) -> -2003880.5 | S26: =SUM(S29:S52) -> -1795535 | V26: =SUM(V29:V52) -> -1772660.2 | Y26: =SUM(Y29:Y52) -> -1798321.7 | AB26: =SUM(AB29:AB52) -> -1784207.5 | AE26: =SUM(AE29:AE52) -> -1751933.7 | AH26: =SUM(AH29:AH52) -> -1952291.7 | AK26: =SUM(AK29:AK52) -> -1569266.8 | AN26: =SUM(D26,G26,J26,M26,P26,S26,V26,Y26,AB26,AE26,AH26,AK26) -> -21293530 | AO26: =SUM(E26,H26,K26,N26,Q26,T26,W26,Z26,AC26,AF26,AI26,AL26) -> -6270684 | AQ26: =AVERAGE(D26,G26,J26) -> -1670879 | AR26: =AVERAGE(E26,H26,K26) -> -1460152.4 | AT26: =SUM(AT28,AT44,AT49,AT50,AT51,AT52) -> -0.74917572 | AV26: =SUM(AV29:AV51) -> -0.81665262 | AW26: =SUM(AW29:AW51) -> -0.70776549 | AX26: =SUM(AX29:AX51) -> -0.69964759 | AY26: =SUM(AY29:AY51) -> -0.69543542 | AZ26: =SUM(AZ29:AZ51) -> -0.66795738 | BA26: =SUM(BA29:BA51) -> -0.70771744 | BB26: =SUM(BB29:BB51) -> -0.72480555 | BC26: =SUM(BC29:BC51) -> -0.718572 | ... BG26: =SUM(BG29:BG51) -> -0.77940602 | BH26: BD | BI26: REAL | BJ26: BD | BK26: REAL | BL26: BD | BM26: REAL | BN26: BD | BO26: REAL
C27: =SUM(D27,G27,J27,M27,P27,S27,V27,Y27,AB27,AE27,AH27,AK27) -> 0 | AN27: =SUM(D27:AK27) -> 0
A28: CMV | C28: =SUM(D28,G28,J28,M28,P28,S28,V28,Y28,AB28,AE28,AH28,AK28) -> -9092664.9 | D28: =SUM(D29:D42) -> -513002.79 | E28: =SUM(E29:E41) -> -600857.5 | G28: =SUM(G29:G42) -> -787441.73 | H28: =SUM(H29:H42) -> -527469.52 | J28: =SUM(J29:J42) -> -793581.04 | K28: =SUM(K29:K42) -> -649970.13 | M28: =SUM(M29:M42) -> -814215.77 | N28: =SUM(N29:N42) -> -895627.39 | P28: =SUM(P29:P42) -> -915143.57 | S28: =SUM(S29:S42) -> -775964.37 | V28: =SUM(V29:V42) -> -748798.22 | Y28: =SUM(Y29:Y42) -> -765940.59 | AB28: =SUM(AB29:AB42) -> -756512.03 | AE28: =SUM(AE29:AE42) -> -734952.49 | AH28: =SUM(AH29:AH42) -> -868795.8 | AK28: =SUM(AK29:AK42) -> -618316.52 | AN28: =SUM(D28,G28,J28,M28,P28,S28,V28,Y28,AB28,AE28,AH28,AK28) -> -9092664.9 | AO28: =SUM(E28,H28,K28,N28,Q28,T28,W28,Z28,AC28,AF28,AI28,AL28) -> -2673924.5 | AQ28: =AVERAGE(D28,G28,J28) -> -698008.52 | AR28: =AVERAGE(E28,H28,K28) -> -592765.72 | AT28: =SUM(AT29:AT42) -> -0.31990956 | AV28: =SUM(AV29:AV42) -> -0.32 | AW28: =SUM(AW29:AW42) -> -0.32 | AX28: =SUM(AX29:AX42) -> -0.31896681 | AY28: =SUM(AY29:AY42) -> -0.32 | AZ28: =SUM(AZ29:AZ42) -> -0.32 | BA28: =SUM(BA29:BA42) -> -0.32 | BB28: =SUM(BB29:BB42) -> -0.32 | BC28: =SUM(BC29:BC42) -> -0.32 | ... BG28: =SUM(BG29:BG42) -> -0.32 | BH28: =D28/$D$24 -> -0.32 | BI28: =E28/$E$24 -> -0.44878234 | BJ28: =G28/$G$24 -> -0.32 | BK28: =H28/$H$24 -> -0.3499834 | BL28: =J28/$J$24 -> -0.31896681 | BM28: =K28/$K$24 -> -0.27268283 | BN28: =M28/$M$24 -> -0.32 | BO28: =N28/$N$24 -> -0.3900331
A29: Carnes Bovina | C29: =SUM(D29,G29,J29,M29,P29,S29,V29,Y29,AB29,AE29,AH29,AK29) -> -4546332.4 | D29: ='04 -Base Orçado 2026'!E32 -> -256501.39 | E29: ='Base Realizado'!D29 -> -170454.81 | G29: ='04 -Base Orçado 2026'!F32 -> -393720.87 | H29: ='Base Realizado'!F29 -> -165532.6 | J29: ='04 -Base Orçado 2026'!G32 -> -396790.52 | K29: ='Base Realizado'!H29 -> -246904.36 | M29: ='04 -Base Orçado 2026'!H32 -> -407107.88 | N29: ='Base Realizado'!K29 -> -214044.67 | P29: ='04 -Base Orçado 2026'!I32 -> -457571.78 | S29: ='04 -Base Orçado 2026'!J32 -> -387982.18 | V29: ='04 -Base Orçado 2026'!K32 -> -374399.11 | Y29: ='04 -Base Orçado 2026'!L32 -> -382970.3 | AB29: ='04 -Base Orçado 2026'!M32 -> -378256.01 | AE29: ='04 -Base Orçado 2026'!N32 -> -367476.25 | AH29: ='04 -Base Orçado 2026'!O32 -> -434397.9 | AK29: ='04 -Base Orçado 2026'!P32 -> -309158.26 | AN29: =SUM(D29:AK29) -> -5343268.9 | AQ29: =AVERAGE(D29,G29,J29) -> -349004.26 | AR29: =AVERAGE(E29,H29,K29) -> -194297.26 | AT29: =IF(ISERROR(C29/C$24),0,(C29/C$24)) -> -0.15995478 | AV29: =IF(ISERROR(D29/D$24),0,(D29/D$24)) -> -0.16 | AW29: =IF(ISERROR(G29/G$24),0,(G29/G$24)) -> -0.16 | AX29: =IF(ISERROR(J29/J$24),0,(J29/J$24)) -> -0.1594834 | AY29: =IF(ISERROR(M29/M$24),0,(M29/M$24)) -> -0.16 | AZ29: =IF(ISERROR(P29/P$24),0,(P29/P$24)) -> -0.16 | BA29: =IF(ISERROR(S29/S$24),0,(S29/S$24)) -> -0.16 | BB29: =IF(ISERROR(V29/V$24),0,(V29/V$24)) -> -0.16 | BC29: =IF(ISERROR(Y29/Y$24),0,(Y29/Y$24)) -> -0.16 | BD29: =IF(ISERROR(AB29/AB$24),0,(AB29/AB$24)) -> -0.16 | BE29: =IF(ISERROR(AE29/AE$24),0,(AE29/AE$24)) -> -0.16 | BF29: =IF(ISERROR(AH29/AH$24),0,(AH29/AH$24)) -> -0.16 | BG29: =IF(ISERROR(AK29/AK$24),0,(AK29/AK$24)) -> -0.16 | BH29: =D29/$D$24 -> -0.16 | BJ29: =G29/$G$24 -> -0.16 | BK29: =H29/$H$24 -> -0.10983319 | BL29: =I29/$G$24 -> 0 | BM29: =J29/$H$24 -> -0.26327606 | BN29: =K29/$G$24 -> -0.10033681 | BO29: =L29/$H$24 -> 0
A30: Carvão | C30: =SUM(D30,G30,J30,M30,P30,S30,V30,Y30,AB30,AE30,AH30,AK30) -> -454633.24 | D30: ='04 -Base Orçado 2026'!E33 -> -25650.139 | E30: ='Base Realizado'!D38 -> -11144 | G30: ='04 -Base Orçado 2026'!F33 -> -39372.087 | H30: ='Base Realizado'!F30 -> -22595.17 | J30: ='04 -Base Orçado 2026'!G33 -> -39679.052 | K30: ='Base Realizado'!H30 -> -57214.49 | M30: ='04 -Base Orçado 2026'!H33 -> -40710.788 | N30: ='Base Realizado'!K30 -> -55787.58 | P30: ='04 -Base Orçado 2026'!I33 -> -45757.178 | S30: ='04 -Base Orçado 2026'!J33 -> -38798.218 | V30: ='04 -Base Orçado 2026'!K33 -> -37439.911 | Y30: ='04 -Base Orçado 2026'!L33 -> -38297.03 | AB30: ='04 -Base Orçado 2026'!M33 -> -37825.601 | AE30: ='04 -Base Orçado 2026'!N33 -> -36747.625 | AH30: ='04 -Base Orçado 2026'!O33 -> -43439.79 | AK30: ='04 -Base Orçado 2026'!P33 -> -30915.826 | AN30: =SUM(D30:AK30) -> -601374.48 | AQ30: =AVERAGE(D30,G30,J30) -> -34900.426 | AR30: =AVERAGE(E30,H30,K30) -> -30317.887 | AT30: =IF(ISERROR(C30/C$24),0,(C30/C$24)) -> -0.015995478 | AV30: =IF(ISERROR(D30/D$24),0,(D30/D$24)) -> -0.016 | AW30: =IF(ISERROR(G30/G$24),0,(G30/G$24)) -> -0.016 | AX30: =IF(ISERROR(J30/J$24),0,(J30/J$24)) -> -0.01594834 | AY30: =IF(ISERROR(M30/M$24),0,(M30/M$24)) -> -0.016 | AZ30: =IF(ISERROR(P30/P$24),0,(P30/P$24)) -> -0.016 | BA30: =IF(ISERROR(S30/S$24),0,(S30/S$24)) -> -0.016 | BB30: =IF(ISERROR(V30/V$24),0,(V30/V$24)) -> -0.016 | BC30: =IF(ISERROR(Y30/Y$24),0,(Y30/Y$24)) -> -0.016 | BD30: =IF(ISERROR(AB30/AB$24),0,(AB30/AB$24)) -> -0.016 | BE30: =IF(ISERROR(AE30/AE$24),0,(AE30/AE$24)) -> -0.016 | BF30: =IF(ISERROR(AH30/AH$24),0,(AH30/AH$24)) -> -0.016 | BG30: =IF(ISERROR(AK30/AK$24),0,(AK30/AK$24)) -> -0.016 | BH30: =D30/$D$24 -> -0.016 | BJ30: =G30/$G$24 -> -0.016 | BK30: =H30/$H$24 -> -0.014992211 | BL30: =I30/$G$24 -> 0 | BM30: =J30/$H$24 -> -0.026327606 | BN30: =K30/$G$24 -> -0.023250783 | BO30: =L30/$H$24 -> 0
A31: Vinhos/Espumantes | C31: =SUM(D31,G31,J31,M31,P31,S31,V31,Y31,AB31,AE31,AH31,AK31) -> -1363899.7 | D31: ='04 -Base Orçado 2026'!E34 -> -76950.418 | E31: ='Base Realizado'!D31 -> -44553.57 | G31: ='04 -Base Orçado 2026'!F34 -> -118116.26 | H31: ='Base Realizado'!F31 -> -104825.14 | J31: ='04 -Base Orçado 2026'!G34 -> -119037.16 | K31: ='Base Realizado'!H31 -> -92357.05 | M31: ='04 -Base Orçado 2026'!H34 -> -122132.37 | N31: ='Base Realizado'!K31 -> -72805.93 | P31: ='04 -Base Orçado 2026'!I34 -> -137271.53 | S31: ='04 -Base Orçado 2026'!J34 -> -116394.66 | V31: ='04 -Base Orçado 2026'!K34 -> -112319.73 | Y31: ='04 -Base Orçado 2026'!L34 -> -114891.09 | AB31: ='04 -Base Orçado 2026'!M34 -> -113476.8 | AE31: ='04 -Base Orçado 2026'!N34 -> -110242.87 | AH31: ='04 -Base Orçado 2026'!O34 -> -130319.37 | AK31: ='04 -Base Orçado 2026'!P34 -> -92747.477 | AN31: =SUM(D31:AK31) -> -1678441.4 | AQ31: =AVERAGE(D31,G31,J31) -> -104701.28 | AR31: =AVERAGE(E31,H31,K31) -> -80578.587 | AT31: =IF(ISERROR(C31/C$24),0,(C31/C$24)) -> -0.047986434 | AV31: =IF(ISERROR(D31/D$24),0,(D31/D$24)) -> -0.048 | AW31: =IF(ISERROR(G31/G$24),0,(G31/G$24)) -> -0.048 | AX31: =IF(ISERROR(J31/J$24),0,(J31/J$24)) -> -0.047845021 | AY31: =IF(ISERROR(M31/M$24),0,(M31/M$24)) -> -0.048 | AZ31: =IF(ISERROR(P31/P$24),0,(P31/P$24)) -> -0.048 | BA31: =IF(ISERROR(S31/S$24),0,(S31/S$24)) -> -0.048 | BB31: =IF(ISERROR(V31/V$24),0,(V31/V$24)) -> -0.048 | BC31: =IF(ISERROR(Y31/Y$24),0,(Y31/Y$24)) -> -0.048 | BD31: =IF(ISERROR(AB31/AB$24),0,(AB31/AB$24)) -> -0.048 | BE31: =IF(ISERROR(AE31/AE$24),0,(AE31/AE$24)) -> -0.048 | BF31: =IF(ISERROR(AH31/AH$24),0,(AH31/AH$24)) -> -0.048 | BG31: =IF(ISERROR(AK31/AK$24),0,(AK31/AK$24)) -> -0.048 | BH31: =D31/$D$24 -> -0.048 | BJ31: =G31/$G$24 -> -0.048 | BK31: =H31/$H$24 -> -0.069552946 | BL31: =I31/$G$24 -> 0 | BM31: =J31/$H$24 -> -0.078982817 | BN31: =K31/$G$24 -> -0.037531991 | BO31: =L31/$H$24 -> 0
