Workbook
Name __FDS_HYPERLINK_TOGGLE_STATE__: "ON"
Name _Order1: 0
Name _Order2: 0
Name a: -15987005.5299987
Name ADM: #REF!
Name ADM: #REF!
Name ADM: #REF!
Name ADM: #REF!
Name ADM: #REF!
Name ADM: #REF!
Name ADM: [0]!ADM
Name ALPHA: #REF!
Name ALPHA: #REF!
Name ALPHA: #REF!
Name ALPHA: #REF!
Name ALPHA: #REF!
Name ALPHA: #REF!
Name Amountin2: "Thousands"
Name AnoDoCalendário: #REF!
Name AnoDoCalendário: #REF!
Name AnoDoCalendário: #REF!
Name Ativo: #REF!
Name Ativo: #REF!
Name Ativo: #REF!
Name Ativo: #REF!
Name AV: #REF!
Name Balanço: #REF!
Name Balanço: #REF!
Name Balanço: #REF!
Name Balanço: #REF!
Name BaseYear: #REF!
Name BaseYear: #REF!
Name BaseYear: #REF!
Name BBQ: #REF!
Name BD_Fluxo_Entradas: #REF!
Name BD_Fluxo_Entradas: #REF!
Name BD_Fluxo_Entradas: #REF!
Name BD_Fluxo_Entradas: #REF!
Name BD_Fluxo_Entradas: #REF!
Name BD_Fluxo_Entradas: #REF!
Name BD_Fluxo_Entradas: #REF!
Name BD_Fluxo_Saidas: #REF!
Name BD_Fluxo_Saidas: #REF!
Name BD_Fluxo_Saidas: #REF!
Name BD_Fluxo_Saidas: #REF!
Name BD_Fluxo_Saidas: #REF!
Name BD_Fluxo_Saidas: #REF!
Name BD_Fluxo_Saidas: #REF!
Name BH: #REF!
Name BreakComercial: '01 Base Realizado'!BreakComercial
Name BreakComercial: #REF!
Name BreakComercial: '04 -Base Orçado 2026'!BreakComercial
Name BreakComercial: #REF!
Name BreakComercial: #REF!
Name BreakComercial: #REF!
Name BreakComercial: '04 -Base Orçado 2026'!BreakComercial
Name BS: #REF!
Name BS_Deferred_Taxes: #REF!
Name BS_Deferred_Taxes: #REF!
Name BS_Deferred_Taxes: #REF!

Sheet 01 Base Realizado
D1: REALIZADO/26 - BASE DE DADOS
B5: DESCRIÇÃO | C5: CONTA | D5: JAN 2026 | E5: AV | F5: FEV 2026 | G5: AV | H5: MAR 2026 | I5: AV | J5: ABR 2026 | K5: MAIO 2026 | L5: JUN 2026 | M5: JUL 2026 | N5: AGO 2026 | O5: SET 2026 | P5: OUT 2026 | Q5: NOV 2026 | R5: DEZ 2026 | T5: TOTAL | Y5: Comentários
B7: CLIENTES | C7: x.x.x.xx.xxxxx | D7: 4761 | T7: 91427.812
B8: TICKET MEDIO | C8: x.x.x.xx.xxxxx | D8: 292 | T8: 300
B10: Rec.Venda no Merc.Int.de Prod.Fabr.Próp. | C10: 3.1.1.01.00004 | T10: 27428344
B11: FATURAMENTO | D11: =SUM(D12:D17)-D12 -> 211614.21 | E11: =SUM(E13:E17) -> 1 | F11: =SUM(F12:F17)-F12 -> 260183.47 | G11: =SUM(G13:G14) -> 1 | H11: =SUM(H12:H14)-H12 -> 401985.89 | I11: =SUM(I13:I14) -> 1 | J11: =SUM(J13:J17) -> 0 | K11: =SUM(K13:K17) -> 0 | L11: =SUM(L13:L17) -> 0 | M11: =SUM(M13:M17) -> 0 | N11: =SUM(N13:N17) -> 0 | O11: =SUM(O13:O17) -> 0 | P11: =SUM(P13:P17) -> 0 | Q11: =SUM(Q13:Q17) -> 0 | R11: =SUM(R13:R17) -> 0 | T11: 27428344 | V11: =SUM(V13:V17) -> 0.344
B12: Gorjetas Recebidas | D12: 24239 | E12: =D12/D$11 -> 0.11454335 | F12: 29204.66 | G12: =F12/F$11 -> 0.11224641 | H12: 46878.24 | I12: =H12/H$11 -> 0.11661663 | T12: 0
B13: Dinheiro/Pix | C13: x.x.x.xx.xxxxx | D13: 6593.74 | E13: =D13/D$11 -> 0.03115925 | F13: =5809.29+10718.3 -> 16527.59 | G13: =F13/F$11 -> 0.063522829 | H13: 23177.13 | I13: =H13/H$11 -> 0.057656576 | T13: 548566.87 | V13: 0.02
B14: Cartão de Débito/ Crédito | C14: x.x.x.xx.xxxxx | D14: 205020.47 | E14: =D14/D$11 -> 0.96884075 | F14: =214451.22+F12 -> 243655.88 | G14: =F14/F$11 -> 0.93647717 | H14: =331930.52+H12 -> 378808.76 | I14: =H14/H$11 -> 0.94234342 | T14: 1919984.1 | V14: 0.07
B15: Evento Faturado | C15: x.x.x.xx.xxxxx | D15: =SUMIFS(B.Receita!$E:$E,B.Receita!$F:$F,'01 Base Realizado'!$B15,B.Receita!$H:$H,'01 Base Realizado'!D$5) -> 0 | T15: 2742834.4 | V15: 0.1
B16: Delivery | C16: x.x.x.xx.xxxxx | D16: =SUMIFS(B.Receita!$E:$E,B.Receita!$F:$F,'01 Base Realizado'!$B16,B.Receita!$H:$H,'01 Base Realizado'!D$5) -> 0 | T16: 4114251.5 | V16: 0.15
B17: Voucher | C17: x.x.x.xx.xxxxx | D17: =SUMIFS(B.Receita!$E:$E,B.Receita!$F:$F,'01 Base Realizado'!$B17,B.Receita!$H:$H,'01 Base Realizado'!D$5) -> 0 | T17: 109713.37 | V17: 0.004
B19: IMPOSTOS | D19: =SUM(D20:D26) -> -461.04 | F19: =SUM(F20:F26) -> -819.32 | H19: =SUM(H20:H26) -> -2604.39 | J19: =SUM(J20:J26) -> 0 | K19: =SUM(K20:K26) -> 0 | L19: =SUM(L20:L26) -> 0 | M19: =SUM(M20:M26) -> 0 | N19: =SUM(N20:N26) -> 0 | O19: =SUM(O20:O26) -> 0 | P19: =SUM(P20:P26) -> 0 | Q19: =SUM(Q20:Q26) -> 0 | R19: =SUM(R20:R26) -> 0 | T19: -2919061.3 | V19: %
B20: (-) ICMS | C20: 3.1.1.02.00002 | D20: =SUMIFS('B. Despesa'!$H:$H,'B. Despesa'!$I:$I,'01 Base Realizado'!D$5,'B. Despesa'!$K:$K,'01 Base Realizado'!$B20) -> -461.04 | F20: =SUMIFS('B. Despesa'!$H:$H,'B. Despesa'!$I:$I,'01 Base Realizado'!F$5,'B. Despesa'!$K:$K,'01 Base Realizado'!$B20) -> 0 | H20: =SUMIFS('B. Despesa'!$H$5:$H$1048576,'B. Despesa'!$I$5:$I$1048576,'01 Base Realizado'!H$5,'B. Despesa'!$K$5:$K$1048576,'01 Base Realizado'!$B20) -> 0 | J20: =SUMIFS('B. Despesa'!$H$5:$H$1048576,'B. Despesa'!$I$5:$I$1048576,'01 Base Realizado'!J$5,'B. Despesa'!$K$5:$K$1048576,'01 Base Realizado'!$B20) -> 0 | K20: =SUMIFS('B. Despesa'!$H$5:$H$1048576,'B. Despesa'!$I$5:$I$1048576,'01 Base Realizado'!K$5,'B. Despesa'!$K$5:$K$1048576,'01 Base Realizado'!$B20) -> 0 | L20: =SUMIFS('B. Despesa'!$H$5:$H$1048576,'B. Despesa'!$I$5:$I$1048576,'01 Base Realizado'!L$5,'B. Despesa'!$K$5:$K$1048576,'01 Base Realizado'!$B20) -> 0 | M20: =SUMIFS('B. Despesa'!$H$5:$H$1048576,'B. Despesa'!$I$5:$I$1048576,'01 Base Realizado'!M$5,'B. Despesa'!$K$5:$K$1048576,'01 Base Realizado'!$B20) -> 0 | N20: =SUMIFS('B. Despesa'!$H$5:$H$1048576,'B. Despesa'!$I$5:$I$1048576,'01 Base Realizado'!N$5,'B. Despesa'!$K$5:$K$1048576,'01 Base Realizado'!$B20) -> 0 | O20: =SUMIFS('B. Despesa'!$H$5:$H$1048576,'B. Despesa'!$I$5:$I$1048576,'01 Base Realizado'!O$5,'B. Despesa'!$K$5:$K$1048576,'01 Base Realizado'!$B20) -> 0 | P20: =SUMIFS('B. Despesa'!$H$5:$H$1048576,'B. Despesa'!$I$5:$I$1048576,'01 Base Realizado'!P$5,'B. Despesa'!$K$5:$K$1048576,'01 Base Realizado'!$B20) -> 0 | Q20: =SUMIFS('B. Despesa'!$H$5:$H$1048576,'B. Despesa'!$I$5:$I$1048576,'01 Base Realizado'!Q$5,'B. Despesa'!$K$5:$K$1048576,'01 Base Realizado'!$B20) -> 0 | R20: =SUMIFS('B. Despesa'!$H$5:$H$1048576,'B. Despesa'!$I$5:$I$1048576,'01 Base Realizado'!R$5,'B. Despesa'!$K$5:$K$1048576,'01 Base Realizado'!$B20) -> 0 | T20: -1097133.7 | V20: 0.04
B21: (-) PIS/Cofins | C21: 3.1.1.02.00003 | D21: =SUMIFS('B. Despesa'!$H:$H,'B. Despesa'!$I:$I,'01 Base Realizado'!D$5,'B. Despesa'!$K:$K,'01 Base Realizado'!$B21) -> 0 | F21: =SUMIFS('B. Despesa'!$H$5:$H$1048576,'B. Despesa'!$I$5:$I$1048576,'01 Base Realizado'!F$5,'B. Despesa'!$K$5:$K$1048576,'01 Base Realizado'!$B21) -> -819.32 | H21: =SUMIFS('B. Despesa'!$H$5:$H$1048576,'B. Despesa'!$I$5:$I$1048576,'01 Base Realizado'!H$5,'B. Despesa'!$K$5:$K$1048576,'01 Base Realizado'!$B21) -> -929.52 | J21: =SUMIFS('B. Despesa'!$H$5:$H$1048576,'B. Despesa'!$I$5:$I$1048576,'01 Base Realizado'!J$5,'B. Despesa'!$K$5:$K$1048576,'01 Base Realizado'!$B21) -> 0 | K21: =SUMIFS('B. Despesa'!$H$5:$H$1048576,'B. Despesa'!$I$5:$I$1048576,'01 Base Realizado'!K$5,'B. Despesa'!$K$5:$K$1048576,'01 Base Realizado'!$B21) -> 0 | L21: =SUMIFS('B. Despesa'!$H$5:$H$1048576,'B. Despesa'!$I$5:$I$1048576,'01 Base Realizado'!L$5,'B. Despesa'!$K$5:$K$1048576,'01 Base Realizado'!$B21) -> 0 | M21: =SUMIFS('B. Despesa'!$H$5:$H$1048576,'B. Despesa'!$I$5:$I$1048576,'01 Base Realizado'!M$5,'B. Despesa'!$K$5:$K$1048576,'01 Base Realizado'!$B21) -> 0 | N21: =SUMIFS('B. Despesa'!$H$5:$H$1048576,'B. Despesa'!$I$5:$I$1048576,'01 Base Realizado'!N$5,'B. Despesa'!$K$5:$K$1048576,'01 Base Realizado'!$B21) -> 0 | O21: =SUMIFS('B. Despesa'!$H$5:$H$1048576,'B. Despesa'!$I$5:$I$1048576,'01 Base Realizado'!O$5,'B. Despesa'!$K$5:$K$1048576,'01 Base Realizado'!$B21) -> 0 | P21: =SUMIFS('B. Despesa'!$H$5:$H$1048576,'B. Despesa'!$I$5:$I$1048576,'01 Base Realizado'!P$5,'B. Despesa'!$K$5:$K$1048576,'01 Base Realizado'!$B21) -> 0 | Q21: =SUMIFS('B. Despesa'!$H$5:$H$1048576,'B. Despesa'!$I$5:$I$1048576,'01 Base Realizado'!Q$5,'B. Despesa'!$K$5:$K$1048576,'01 Base Realizado'!$B21) -> 0 | R21: =SUMIFS('B. Despesa'!$H$5:$H$1048576,'B. Despesa'!$I$5:$I$1048576,'01 Base Realizado'!R$5,'B. Despesa'!$K$5:$K$1048576,'01 Base Realizado'!$B21) -> 0 | T21: -822850.31 | V21: 0.03
B22: (-) PIS/Pasep | C22: 3.1.1.02.00004 | D22: =SUMIFS('B. Despesa'!$H:$H,'B. Despesa'!$I:$I,'01 Base Realizado'!D$5,'B. Despesa'!$K:$K,'01 Base Realizado'!$B22) -> 0 | F22: =SUMIFS('B. Despesa'!$H$5:$H$1048576,'B. Despesa'!$I$5:$I$1048576,'01 Base Realizado'!F$5,'B. Despesa'!$K$5:$K$1048576,'01 Base Realizado'!$B22) -> 0 | H22: =SUMIFS('B. Despesa'!$H$5:$H$1048576,'B. Despesa'!$I$5:$I$1048576,'01 Base Realizado'!H$5,'B. Despesa'!$K$5:$K$1048576,'01 Base Realizado'!$B22) -> 0 | J22: =SUMIFS('B. Despesa'!$H$5:$H$1048576,'B. Despesa'!$I$5:$I$1048576,'01 Base Realizado'!J$5,'B. Despesa'!$K$5:$K$1048576,'01 Base Realizado'!$B22) -> 0 | K22: =SUMIFS('B. Despesa'!$H$5:$H$1048576,'B. Despesa'!$I$5:$I$1048576,'01 Base Realizado'!K$5,'B. Despesa'!$K$5:$K$1048576,'01 Base Realizado'!$B22) -> 0 | L22: =SUMIFS('B. Despesa'!$H$5:$H$1048576,'B. Despesa'!$I$5:$I$1048576,'01 Base Realizado'!L$5,'B. Despesa'!$K$5:$K$1048576,'01 Base Realizado'!$B22) -> 0 | M22: =SUMIFS('B. Despesa'!$H$5:$H$1048576,'B. Despesa'!$I$5:$I$1048576,'01 Base Realizado'!M$5,'B. Despesa'!$K$5:$K$1048576,'01 Base Realizado'!$B22) -> 0 | N22: =SUMIFS('B. Despesa'!$H$5:$H$1048576,'B. Despesa'!$I$5:$I$1048576,'01 Base Realizado'!N$5,'B. Despesa'!$K$5:$K$1048576,'01 Base Realizado'!$B22) -> 0 | O22: =SUMIFS('B. Despesa'!$H$5:$H$1048576,'B. Despesa'!$I$5:$I$1048576,'01 Base Realizado'!O$5,'B. Despesa'!$K$5:$K$1048576,'01 Base Realizado'!$B22) -> 0 | P22: =SUMIFS('B. Despesa'!$H$5:$H$1048576,'B. Despesa'!$I$5:$I$1048576,'01 Base Realizado'!P$5,'B. Despesa'!$K$5:$K$1048576,'01 Base Realizado'!$B22) -> 0 | Q22: =SUMIFS('B. Despesa'!$H$5:$H$1048576,'B. Despesa'!$I$5:$I$1048576,'01 Base Realizado'!Q$5,'B. Despesa'!$K$5:$K$1048576,'01 Base Realizado'!$B22) -> 0 | R22: =SUMIFS('B. Despesa'!$H$5:$H$1048576,'B. Despesa'!$I$5:$I$1048576,'01 Base Realizado'!R$5,'B. Despesa'!$K$5:$K$1048576,'01 Base Realizado'!$B22) -> 0 | T22: -178284.23 | V22: 0.0065
B23: (-) ISS | C23: 5.4.1.03.00035 | D23: =SUMIFS('B. Despesa'!$H:$H,'B. Despesa'!$I:$I,'01 Base Realizado'!D$5,'B. Despesa'!$K:$K,'01 Base Realizado'!$B23) -> 0 | F23: =SUMIFS('B. Despesa'!$H$5:$H$1048576,'B. Despesa'!$I$5:$I$1048576,'01 Base Realizado'!F$5,'B. Despesa'!$K$5:$K$1048576,'01 Base Realizado'!$B23) -> 0 | H23: =SUMIFS('B. Despesa'!$H$5:$H$1048576,'B. Despesa'!$I$5:$I$1048576,'01 Base Realizado'!H$5,'B. Despesa'!$K$5:$K$1048576,'01 Base Realizado'!$B23) -> 0 | J23: =SUMIFS('B. Despesa'!$H$5:$H$1048576,'B. Despesa'!$I$5:$I$1048576,'01 Base Realizado'!J$5,'B. Despesa'!$K$5:$K$1048576,'01 Base Realizado'!$B23) -> 0 | K23: =SUMIFS('B. Despesa'!$H$5:$H$1048576,'B. Despesa'!$I$5:$I$1048576,'01 Base Realizado'!K$5,'B. Despesa'!$K$5:$K$1048576,'01 Base Realizado'!$B23) -> 0 | L23: =SUMIFS('B. Despesa'!$H$5:$H$1048576,'B. Despesa'!$I$5:$I$1048576,'01 Base Realizado'!L$5,'B. Despesa'!$K$5:$K$1048576,'01 Base Realizado'!$B23) -> 0 | M23: =SUMIFS('B. Despesa'!$H$5:$H$1048576,'B. Despesa'!$I$5:$I$1048576,'01 Base Realizado'!M$5,'B. Despesa'!$K$5:$K$1048576,'01 Base Realizado'!$B23) -> 0 | N23: =SUMIFS('B. Despesa'!$H$5:$H$1048576,'B. Despesa'!$I$5:$I$1048576,'01 Base Realizado'!N$5,'B. Despesa'!$K$5:$K$1048576,'01 Base Realizado'!$B23) -> 0 | O23: =SUMIFS('B. Despesa'!$H$5:$H$1048576,'B. Despesa'!$I$5:$I$1048576,'01 Base Realizado'!O$5,'B. Despesa'!$K$5:$K$1048576,'01 Base Realizado'!$B23) -> 0 | P23: =SUMIFS('B. Despesa'!$H$5:$H$1048576,'B. Despesa'!$I$5:$I$1048576,'01 Base Realizado'!P$5,'B. Despesa'!$K$5:$K$1048576,'01 Base Realizado'!$B23) -> 0 | Q23: =SUMIFS('B. Despesa'!$H$5:$H$1048576,'B. Despesa'!$I$5:$I$1048576,'01 Base Realizado'!Q$5,'B. Despesa'!$K$5:$K$1048576,'01 Base Realizado'!$B23) -> 0 | R23: =SUMIFS('B. Despesa'!$H$5:$H$1048576,'B. Despesa'!$I$5:$I$1048576,'01 Base Realizado'!R$5,'B. Despesa'!$K$5:$K$1048576,'01 Base Realizado'!$B23) -> 0 | T23: 0 | V23: 0
B24: (-) IRPJ/CSLL | C24: 6.1.1.01.00001 | D24: =SUMIFS('B. Despesa'!$H:$H,'B. Despesa'!$I:$I,'01 Base Realizado'!D$5,'B. Despesa'!$K:$K,'01 Base Realizado'!$B24) -> 0 | F24: =SUMIFS('B. Despesa'!$H$5:$H$1048576,'B. Despesa'!$I$5:$I$1048576,'01 Base Realizado'!F$5,'B. Despesa'!$K$5:$K$1048576,'01 Base Realizado'!$B24) -> 0 | H24: =SUMIFS('B. Despesa'!$H$5:$H$1048576,'B. Despesa'!$I$5:$I$1048576,'01 Base Realizado'!H$5,'B. Despesa'!$K$5:$K$1048576,'01 Base Realizado'!$B24) -> -1674.87 | J24: =SUMIFS('B. Despesa'!$H$5:$H$1048576,'B. Despesa'!$I$5:$I$1048576,'01 Base Realizado'!J$5,'B. Despesa'!$K$5:$K$1048576,'01 Base Realizado'!$B24) -> 0 | K24: =SUMIFS('B. Despesa'!$H$5:$H$1048576,'B. Despesa'!$I$5:$I$1048576,'01 Base Realizado'!K$5,'B. Despesa'!$K$5:$K$1048576,'01 Base Realizado'!$B24) -> 0 | L24: =SUMIFS('B. Despesa'!$H$5:$H$1048576,'B. Despesa'!$I$5:$I$1048576,'01 Base Realizado'!L$5,'B. Despesa'!$K$5:$K$1048576,'01 Base Realizado'!$B24) -> 0 | M24: =SUMIFS('B. Despesa'!$H$5:$H$1048576,'B. Despesa'!$I$5:$I$1048576,'01 Base Realizado'!M$5,'B. Despesa'!$K$5:$K$1048576,'01 Base Realizado'!$B24) -> 0 | N24: =SUMIFS('B. Despesa'!$H$5:$H$1048576,'B. Despesa'!$I$5:$I$1048576,'01 Base Realizado'!N$5,'B. Despesa'!$K$5:$K$1048576,'01 Base Realizado'!$B24) -> 0 | O24: =SUMIFS('B. Despesa'!$H$5:$H$1048576,'B. Despesa'!$I$5:$I$1048576,'01 Base Realizado'!O$5,'B. Despesa'!$K$5:$K$1048576,'01 Base Realizado'!$B24) -> 0 | P24: =SUMIFS('B. Despesa'!$H$5:$H$1048576,'B. Despesa'!$I$5:$I$1048576,'01 Base Realizado'!P$5,'B. Despesa'!$K$5:$K$1048576,'01 Base Realizado'!$B24) -> 0 | Q24: =SUMIFS('B. Despesa'!$H$5:$H$1048576,'B. Despesa'!$I$5:$I$1048576,'01 Base Realizado'!Q$5,'B. Despesa'!$K$5:$K$1048576,'01 Base Realizado'!$B24) -> 0 | R24: =SUMIFS('B. Despesa'!$H$5:$H$1048576,'B. Despesa'!$I$5:$I$1048576,'01 Base Realizado'!R$5,'B. Despesa'!$K$5:$K$1048576,'01 Base Realizado'!$B24) -> 0 | T24: -524566.87 | V24: 0.08 | W24: 0.15
C25: 6.1.1.01.00002 | D25: =SUMIFS('B. Despesa'!$H:$H,'B. Despesa'!$I:$I,'01 Base Realizado'!D$5,'B. Despesa'!$K:$K,'01 Base Realizado'!$B25) -> 0 | F25: =SUMIFS('B. Despesa'!$H$5:$H$1048576,'B. Despesa'!$I$5:$I$1048576,'01 Base Realizado'!F$5,'B. Despesa'!$K$5:$K$1048576,'01 Base Realizado'!$B25) -> 0 | H25: =SUMIFS('B. Despesa'!$H$5:$H$1048576,'B. Despesa'!$I$5:$I$1048576,'01 Base Realizado'!H$5,'B. Despesa'!$K$5:$K$1048576,'01 Base Realizado'!$B25) -> 0 | J25: =SUMIFS('B. Despesa'!$H$5:$H$1048576,'B. Despesa'!$I$5:$I$1048576,'01 Base Realizado'!J$5,'B. Despesa'!$K$5:$K$1048576,'01 Base Realizado'!$B25) -> 0 | K25: =SUMIFS('B. Despesa'!$H$5:$H$1048576,'B. Despesa'!$I$5:$I$1048576,'01 Base Realizado'!K$5,'B. Despesa'!$K$5:$K$1048576,'01 Base Realizado'!$B25) -> 0 | L25: =SUMIFS('B. Despesa'!$H$5:$H$1048576,'B. Despesa'!$I$5:$I$1048576,'01 Base Realizado'!L$5,'B. Despesa'!$K$5:$K$1048576,'01 Base Realizado'!$B25) -> 0 | M25: =SUMIFS('B. Despesa'!$H$5:$H$1048576,'B. Despesa'!$I$5:$I$1048576,'01 Base Realizado'!M$5,'B. Despesa'!$K$5:$K$1048576,'01 Base Realizado'!$B25) -> 0 | N25: =SUMIFS('B. Despesa'!$H$5:$H$1048576,'B. Despesa'!$I$5:$I$1048576,'01 Base Realizado'!N$5,'B. Despesa'!$K$5:$K$1048576,'01 Base Realizado'!$B25) -> 0 | O25: =SUMIFS('B. Despesa'!$H$5:$H$1048576,'B. Despesa'!$I$5:$I$1048576,'01 Base Realizado'!O$5,'B. Despesa'!$K$5:$K$1048576,'01 Base Realizado'!$B25) -> 0 | P25: =SUMIFS('B. Despesa'!$H$5:$H$1048576,'B. Despesa'!$I$5:$I$1048576,'01 Base Realizado'!P$5,'B. Despesa'!$K$5:$K$1048576,'01 Base Realizado'!$B25) -> 0 | Q25: =SUMIFS('B. Despesa'!$H$5:$H$1048576,'B. Despesa'!$I$5:$I$1048576,'01 Base Realizado'!Q$5,'B. Despesa'!$K$5:$K$1048576,'01 Base Realizado'!$B25) -> 0 | R25: =SUMIFS('B. Despesa'!$H$5:$H$1048576,'B. Despesa'!$I$5:$I$1048576,'01 Base Realizado'!R$5,'B. Despesa'!$K$5:$K$1048576,'01 Base Realizado'!$B25) -> 0 | T25: -296226.11 | V25: 0.12 | W25: 0.09
B26: IRPJ | C26: 4.1.2.04.00002 | D26: =SUMIFS('B. Despesa'!$H:$H,'B. Despesa'!$I:$I,'01 Base Realizado'!D$5,'B. Despesa'!$K:$K,'01 Base Realizado'!$B26) -> 0 | F26: 0 | H26: 0 | J26: 0 | K26: 0 | L26: 0 | M26: 0 | N26: 0 | O26: 0 | P26: 0 | Q26: 0 | R26: 0 | T26: 0 | V26: 0
B27: CSLL | C27: 4.1.2.04.00001 | D27: =SUMIFS('B. Despesa'!$H:$H,'B. Despesa'!$I:$I,'01 Base Realizado'!D$5,'B. Despesa'!$K:$K,'01 Base Realizado'!$B27) -> 0 | F27: 0 | H27: 0 | J27: 0 | K27: 0 | L27: 0 | M27: 0 | N27: 0 | O27: 0 | P27: 0 | Q27: 0 | R27: 0 | T27: 0 | V27: 0
B28: CUSTOS DOS PRODUTOS VENDIDOS | D28: =SUM(D29:D34)-D35 -> 40294.722 | F28: =SUM(F29:F34)-F35 -> 68959.922 | H28: =SUM(H29:H34)-H35 -> 77942.836 | J28: =SUM(J29:J35) -> 0 | K28: =SUM(K29:K35) -> 0 | L28: =SUM(L29:L35) -> 0 | M28: =SUM(M29:M35) -> 0 | N28: =SUM(N29:N35) -> 0 | O28: =SUM(O29:O35) -> 0 | P28: =SUM(P29:P35) -> 0 | Q28: =SUM(Q29:Q35) -> 0 | R28: =SUM(R29:R35) -> 0 | T28: -8105624.1 | V28: =SUM(V29:V35) -> 0.79 | W28: 1 | X28: =V28-W28 -> -0.21
B29: Estoque Inicial | C29: 5.4.1.01.00002 | D29: ='SALDO INICIAL DEZEMBRO'!B11 -> 141723.27 | F29: =-D33 -> 127034.79 | H29: =-F33 -> 122710.94 | J29: =SUMIFS('B. Despesa'!$H$5:$H$1048576,'B. Despesa'!$I$5:$I$1048576,'01 Base Realizado'!J$5,'B. Despesa'!$K$5:$K$1048576,'01 Base Realizado'!$B29) -> 0 | K29: =SUMIFS('B. Despesa'!$H$5:$H$1048576,'B. Despesa'!$I$5:$I$1048576,'01 Base Realizado'!K$5,'B. Despesa'!$K$5:$K$1048576,'01 Base Realizado'!$B29) -> 0 | L29: =SUMIFS('B. Despesa'!$H$5:$H$1048576,'B. Despesa'!$I$5:$I$1048576,'01 Base Realizado'!L$5,'B. Despesa'!$K$5:$K$1048576,'01 Base Realizado'!$B29) -> 0 | M29: =SUMIFS('B. Despesa'!$H$5:$H$1048576,'B. Despesa'!$I$5:$I$1048576,'01 Base Realizado'!M$5,'B. Despesa'!$K$5:$K$1048576,'01 Base Realizado'!$B29) -> 0 | N29: =SUMIFS('B. Despesa'!$H$5:$H$1048576,'B. Despesa'!$I$5:$I$1048576,'01 Base Realizado'!N$5,'B. Despesa'!$K$5:$K$1048576,'01 Base Realizado'!$B29) -> 0 | O29: =SUMIFS('B. Despesa'!$H$5:$H$1048576,'B. Despesa'!$I$5:$I$1048576,'01 Base Realizado'!O$5,'B. Despesa'!$K$5:$K$1048576,'01 Base Realizado'!$B29) -> 0 | P29: =SUMIFS('B. Despesa'!$H$5:$H$1048576,'B. Despesa'!$I$5:$I$1048576,'01 Base Realizado'!P$5,'B. Despesa'!$K$5:$K$1048576,'01 Base Realizado'!$B29) -> 0 | Q29: =SUMIFS('B. Despesa'!$H$5:$H$1048576,'B. Despesa'!$I$5:$I$1048576,'01 Base Realizado'!Q$5,'B. Despesa'!$K$5:$K$1048576,'01 Base Realizado'!$B29) -> 0 | R29: =SUMIFS('B. Despesa'!$H$5:$H$1048576,'B. Despesa'!$I$5:$I$1048576,'01 Base Realizado'!R$5,'B. Despesa'!$K$5:$K$1048576,'01 Base Realizado'!$B29) -> 0 | T29: -4052812.1 | V29: 0.5
B30: Compra Mês | C30: 5.4.1.01.00003 | D30: =-SUMIFS('B. Despesa'!$H$5:$H$1048576,'B. Despesa'!$I$5:$I$1048576,'01 Base Realizado'!D$5,'B. Despesa'!$K$5:$K$1048576,'01 Base Realizado'!$B30) -> 27342.98 | E30: =D30/D$11 -> 0.12921146 | F30: =-SUMIFS('B. Despesa'!$H$5:$H$1048576,'B. Despesa'!$I$5:$I$1048576,'01 Base Realizado'!F$5,'B. Despesa'!$K$5:$K$1048576,'01 Base Realizado'!$B30) -> 61684.24 | G30: =F30/F$11 -> 0.23707978 | H30: =-SUMIFS('B. Despesa'!$H$5:$H$1048576,'B. Despesa'!$I$5:$I$1048576,'01 Base Realizado'!H$5,'B. Despesa'!$K$5:$K$1048576,'01 Base Realizado'!$B30) -> 91589.48 | I30: =H30/H$11 -> 0.22784252 | J30: =SUMIFS('B. Despesa'!$H$5:$H$1048576,'B. Despesa'!$I$5:$I$1048576,'01 Base Realizado'!J$5,'B. Despesa'!$K$5:$K$1048576,'METRICS MDNA'!$B2) -> 0 | K30: =SUMIFS('B. Despesa'!$H$5:$H$1048576,'B. Despesa'!$I$5:$I$1048576,'01 Base Realizado'!K$5,'B. Despesa'!$K$5:$K$1048576,'METRICS MDNA'!$B2) -> 0 | L30: =SUMIFS('B. Despesa'!$H$5:$H$1048576,'B. Despesa'!$I$5:$I$1048576,'01 Base Realizado'!L$5,'B. Despesa'!$K$5:$K$1048576,'METRICS MDNA'!$B2) -> 0 | M30: =SUMIFS('B. Despesa'!$H$5:$H$1048576,'B. Despesa'!$I$5:$I$1048576,'01 Base Realizado'!M$5,'B. Despesa'!$K$5:$K$1048576,'METRICS MDNA'!$B2) -> 0 | N30: =SUMIFS('B. Despesa'!$H$5:$H$1048576,'B. Despesa'!$I$5:$I$1048576,'01 Base Realizado'!N$5,'B. Despesa'!$K$5:$K$1048576,'METRICS MDNA'!$B2) -> 0 | O30: =SUMIFS('B. Despesa'!$H$5:$H$1048576,'B. Despesa'!$I$5:$I$1048576,'01 Base Realizado'!O$5,'B. Despesa'!$K$5:$K$1048576,'METRICS MDNA'!$B2) -> 0 | P30: =SUMIFS('B. Despesa'!$H$5:$H$1048576,'B. Despesa'!$I$5:$I$1048576,'01 Base Realizado'!P$5,'B. Despesa'!$K$5:$K$1048576,'METRICS MDNA'!$B2) -> 0 | Q30: =SUMIFS('B. Despesa'!$H$5:$H$1048576,'B. Despesa'!$I$5:$I$1048576,'01 Base Realizado'!Q$5,'B. Despesa'!$K$5:$K$1048576,'METRICS MDNA'!$B2) -> 0 | R30: =SUMIFS('B. Despesa'!$H$5:$H$1048576,'B. Despesa'!$I$5:$I$1048576,'01 Base Realizado'!R$5,'B. Despesa'!$K$5:$K$1048576,'METRICS MDNA'!$B2) -> 0 | T30: -405281.21 | V30: 0.05 | Y30: Valor de compra em média estavel entre Fev e Mar/26, e baixo volume de compras em Jan/26 por estoque alto
B31: Transferência de Estoque Entrada | E31: =D31/D$11 -> 0 | F31: ='TRANSF. ESTOQUE FEV '!B11 -> 8902.82 | G31: =F31/F$11 -> 0.03421747 | H31: ='TRANSF. ESTOQUE FEV '!E8 -> 9675.06 | I31: =H31/H$11 -> 0.024068158 | Y31: Houve falha na apuração de Jan/26
B32: Transferência de Estoque Saída | E32: =D32/D$11 -> 0 | F32: =-'TRANSF. ESTOQUE FEV '!B17 -> -1110.51 | G32: =-F32/F$11 -> 0.0042681804 | H32: =-'TRANSF. ESTOQUE FEV '!E17 -> -98.85 | I32: =H32/H$11 -> -0.00024590415 | Y32: Houve falha na apuração de Jan/26
B33: Estoque Final | C33: 5.4.1.01.00006 | D33: =-SUMIFS(Inventário!$L:$L,Inventário!$N:$N,'01 Base Realizado'!D$5,Inventário!$P:$P,'01 Base Realizado'!$B33) -> -127034.79 | E33: =-D33/D$11 -> 0.60031312 | F33: =-SUMIFS(Inventário!$L:$L,Inventário!$N:$N,'01 Base Realizado'!F$5,Inventário!$P:$P,'01 Base Realizado'!$B33) -> -122710.94 | G33: =-F33/F$11 -> 0.47163236 | H33: =-SUMIFS(Inventário!$L:$L,Inventário!$N:$N,'01 Base Realizado'!H$5,Inventário!$P:$P,'01 Base Realizado'!$B33) -> -142103.99 | I33: =-H33/H$11 -> 0.35350492 | J33: =SUMIFS('B. Despesa'!$H$5:$H$1048576,'B. Despesa'!$I$5:$I$1048576,'01 Base Realizado'!J$5,'B. Despesa'!$K$5:$K$1048576,'01 Base Realizado'!$B33) -> 0 | K33: =SUMIFS('B. Despesa'!$H$5:$H$1048576,'B. Despesa'!$I$5:$I$1048576,'01 Base Realizado'!K$5,'B. Despesa'!$K$5:$K$1048576,'01 Base Realizado'!$B33) -> 0 | L33: =SUMIFS('B. Despesa'!$H$5:$H$1048576,'B. Despesa'!$I$5:$I$1048576,'01 Base Realizado'!L$5,'B. Despesa'!$K$5:$K$1048576,'01 Base Realizado'!$B33) -> 0 | M33: =SUMIFS('B. Despesa'!$H$5:$H$1048576,'B. Despesa'!$I$5:$I$1048576,'01 Base Realizado'!M$5,'B. Despesa'!$K$5:$K$1048576,'01 Base Realizado'!$B33) -> 0 | N33: =SUMIFS('B. Despesa'!$H$5:$H$1048576,'B. Despesa'!$I$5:$I$1048576,'01 Base Realizado'!N$5,'B. Despesa'!$K$5:$K$1048576,'01 Base Realizado'!$B33) -> 0 | O33: =SUMIFS('B. Despesa'!$H$5:$H$1048576,'B. Despesa'!$I$5:$I$1048576,'01 Base Realizado'!O$5,'B. Despesa'!$K$5:$K$1048576,'01 Base Realizado'!$B33) -> 0 | P33: =SUMIFS('B. Despesa'!$H$5:$H$1048576,'B. Despesa'!$I$5:$I$1048576,'01 Base Realizado'!P$5,'B. Despesa'!$K$5:$K$1048576,'01 Base Realizado'!$B33) -> 0 | Q33: =SUMIFS('B. Despesa'!$H$5:$H$1048576,'B. Despesa'!$I$5:$I$1048576,'01 Base Realizado'!Q$5,'B. Despesa'!$K$5:$K$1048576,'01 Base Realizado'!$B33) -> 0 | R33: =SUMIFS('B. Despesa'!$H$5:$H$1048576,'B. Despesa'!$I$5:$I$1048576,'01 Base Realizado'!R$5,'B. Despesa'!$K$5:$K$1048576,'01 Base Realizado'!$B33) -> 0 | T33: -1215843.6 | V33: 0.15 | Y33: Estoque de março, 87k (61%)= vinhos e champ. o saldo restante de 55k, média de 21 dias de estoque! Atuar em redução
B34: Bonificações | C34: 5.4.1.01.00007 | H34: =SUMIFS('B. Despesa'!$H$5:$H$1048576,'B. Despesa'!$I$5:$I$1048576,'01 Base Realizado'!H$5,'B. Despesa'!$K$5:$K$1048576,'01 Base Realizado'!$B34) -> 0 | J34: =SUMIFS('B. Despesa'!$H$5:$H$1048576,'B. Despesa'!$I$5:$I$1048576,'01 Base Realizado'!J$5,'B. Despesa'!$K$5:$K$1048576,'01 Base Realizado'!$B34) -> 0 | K34: =SUMIFS('B. Despesa'!$H$5:$H$1048576,'B. Despesa'!$I$5:$I$1048576,'01 Base Realizado'!K$5,'B. Despesa'!$K$5:$K$1048576,'01 Base Realizado'!$B34) -> 0 | L34: =SUMIFS('B. Despesa'!$H$5:$H$1048576,'B. Despesa'!$I$5:$I$1048576,'01 Base Realizado'!L$5,'B. Despesa'!$K$5:$K$1048576,'01 Base Realizado'!$B34) -> 0 | M34: =SUMIFS('B. Despesa'!$H$5:$H$1048576,'B. Despesa'!$I$5:$I$1048576,'01 Base Realizado'!M$5,'B. Despesa'!$K$5:$K$1048576,'01 Base Realizado'!$B34) -> 0 | N34: =SUMIFS('B. Despesa'!$H$5:$H$1048576,'B. Despesa'!$I$5:$I$1048576,'01 Base Realizado'!N$5,'B. Despesa'!$K$5:$K$1048576,'01 Base Realizado'!$B34) -> 0 | O34: =SUMIFS('B. Despesa'!$H$5:$H$1048576,'B. Despesa'!$I$5:$I$1048576,'01 Base Realizado'!O$5,'B. Despesa'!$K$5:$K$1048576,'01 Base Realizado'!$B34) -> 0 | P34: =SUMIFS('B. Despesa'!$H$5:$H$1048576,'B. Despesa'!$I$5:$I$1048576,'01 Base Realizado'!P$5,'B. Despesa'!$K$5:$K$1048576,'01 Base Realizado'!$B34) -> 0 | Q34: =SUMIFS('B. Despesa'!$H$5:$H$1048576,'B. Despesa'!$I$5:$I$1048576,'01 Base Realizado'!Q$5,'B. Despesa'!$K$5:$K$1048576,'01 Base Realizado'!$B34) -> 0 | R34: =SUMIFS('B. Despesa'!$H$5:$H$1048576,'B. Despesa'!$I$5:$I$1048576,'01 Base Realizado'!R$5,'B. Despesa'!$K$5:$K$1048576,'01 Base Realizado'!$B34) -> 0 | T34: -405281.21 | V34: 0.05
B35: (-) Reclassificação CMV | C35: 5.4.1.01.00008 | D35: =-D54 -> 1736.74 | F35: =-F54 -> 4840.47 | H35: 3829.81 | J35: =SUMIFS('B. Despesa'!$H$5:$H$1048576,'B. Despesa'!$I$5:$I$1048576,'01 Base Realizado'!J$5,'B. Despesa'!$K$5:$K$1048576,'01 Base Realizado'!$B35) -> 0 | K35: =SUMIFS('B. Despesa'!$H$5:$H$1048576,'B. Despesa'!$I$5:$I$1048576,'01 Base Realizado'!K$5,'B. Despesa'!$K$5:$K$1048576,'01 Base Realizado'!$B35) -> 0 | L35: =SUMIFS('B. Despesa'!$H$5:$H$1048576,'B. Despesa'!$I$5:$I$1048576,'01 Base Realizado'!L$5,'B. Despesa'!$K$5:$K$1048576,'01 Base Realizado'!$B35) -> 0 | M35: =SUMIFS('B. Despesa'!$H$5:$H$1048576,'B. Despesa'!$I$5:$I$1048576,'01 Base Realizado'!M$5,'B. Despesa'!$K$5:$K$1048576,'01 Base Realizado'!$B35) -> 0 | N35: =SUMIFS('B. Despesa'!$H$5:$H$1048576,'B. Despesa'!$I$5:$I$1048576,'01 Base Realizado'!N$5,'B. Despesa'!$K$5:$K$1048576,'01 Base Realizado'!$B35) -> 0 | O35: =SUMIFS('B. Despesa'!$H$5:$H$1048576,'B. Despesa'!$I$5:$I$1048576,'01 Base Realizado'!O$5,'B. Despesa'!$K$5:$K$1048576,'01 Base Realizado'!$B35) -> 0 | P35: =SUMIFS('B. Despesa'!$H$5:$H$1048576,'B. Despesa'!$I$5:$I$1048576,'01 Base Realizado'!P$5,'B. Despesa'!$K$5:$K$1048576,'01 Base Realizado'!$B35) -> 0 | Q35: =SUMIFS('B. Despesa'!$H$5:$H$1048576,'B. Despesa'!$I$5:$I$1048576,'01 Base Realizado'!Q$5,'B. Despesa'!$K$5:$K$1048576,'01 Base Realizado'!$B35) -> 0 | R35: =SUMIFS('B. Despesa'!$H$5:$H$1048576,'B. Despesa'!$I$5:$I$1048576,'01 Base Realizado'!R$5,'B. Despesa'!$K$5:$K$1048576,'01 Base Realizado'!$B35) -> 0 | T35: -324224.96 | V35: 0.04 | Y35: Em meados de Jan/26 iniciou-se os controles via sistema Everest e em Março houve uma redução de aproveitamento de aparas
B37: ÍNDICE | D37: =-D39/D38 -> 0.19083172 | F37: =-F39/F38 -> 0.2658807 | H37: =-H39/H38 -> 0.19515885 | T37: 0.32 | Y37: O motivo pelo qual houve um descolamento se dá pela refeição, ajustes de fichas tecnicas e preço de venda.
B38: RECEITA LÍQUIDA | D38: =D11+D19 -> 211153.17 | F38: =F11+F19 -> 259364.15 | H38: =H11+H19 -> 399381.5 | J38: =J11+J19 -> 0 | K38: =K11+K19 -> 0 | L38: =L11+L19 -> 0 | M38: =M11+M19 -> 0 | N38: =N11+N19 -> 0 | O38: =O11+O19 -> 0 | P38: =P11+P19 -> 0 | Q38: =Q11+Q19 -> 0 | R38: =R11+R19 -> 0 | T38: 25330075 | Y38: Utilizamos as planilhas de excel para efetuar os lançamento no sistema, em Abril será 100% plan Everest
B39: CMV | D39: =-D28 -> -40294.722 | F39: =-F28 -> -68959.922 | H39: =-H28 -> -77942.836 | J39: =-J28 -> 0 | K39: =-K28 -> 0 | L39: =-L28 -> 0 | M39: =-M28 -> 0 | N39: =-N28 -> 0 | O39: =-O28 -> 0 | P39: =-P28 -> 0 | Q39: =-Q28 -> 0 | R39: =-R28 -> 0 | T39: 8105624.1
B41: PESSOAL | D41: =SUM(D42:D66) -> -50083.16 | E41: =SUM(E42:E66) -> 0.23718877 | F41: =SUM(F42:F66) -> -44395.31 | G41: =SUM(G42:G66) -> 0.1711698 | H41: =SUM(H42:H66) -> -61583.06 | I41: =SUM(I42:I66) -> 0.15419608 | J41: =SUM(J42:J66) -> 0 | K41: =SUM(K42:K66) -> 0 | ... R41: =SUM(R42:R66) -> 0 | T41: -6739721.6 | V41: %
B42: Salários e Ordenados | C42: 5.4.1.02.00001 | D42: =SUMIFS('B. Despesa'!$H:$H,'B. Despesa'!$I:$I,'01 Base Realizado'!D$5,'B. Despesa'!$K:$K,'01 Base Realizado'!$B42) -> -19897.66 | E42: =-D42/D$38 -> 0.0942333 | F42: =SUMIFS('B. Despesa'!$H$5:$H$1048576,'B. Despesa'!$I$5:$I$1048576,'01 Base Realizado'!F$5,'B. Despesa'!$K$5:$K$1048576,'01 Base Realizado'!$B42) -> -24163.94 | G42: =-F42/F$38 -> 0.093166076 | H42: =SUMIFS('B. Despesa'!$H$5:$H$1048576,'B. Despesa'!$I$5:$I$1048576,'01 Base Realizado'!H$5,'B. Despesa'!$K$5:$K$1048576,'01 Base Realizado'!$B42) -> -29225.09 | I42: =-H42/H$38 -> 0.073175873 | J42: =SUMIFS('B. Despesa'!$H$5:$H$1048576,'B. Despesa'!$I$5:$I$1048576,'01 Base Realizado'!J$5,'B. Despesa'!$K$5:$K$1048576,'01 Base Realizado'!$B42) -> 0 | K42: =SUMIFS('B. Despesa'!$H$5:$H$1048576,'B. Despesa'!$I$5:$I$1048576,'01 Base Realizado'!K$5,'B. Despesa'!$K$5:$K$1048576,'01 Base Realizado'!$B42) -> 0 | L42: =SUMIFS('B. Despesa'!$H$5:$H$1048576,'B. Despesa'!$I$5:$I$1048576,'01 Base Realizado'!L$5,'B. Despesa'!$K$5:$K$1048576,'01 Base Realizado'!$B42) -> 0 | M42: =SUMIFS('B. Despesa'!$H$5:$H$1048576,'B. Despesa'!$I$5:$I$1048576,'01 Base Realizado'!M$5,'B. Despesa'!$K$5:$K$1048576,'01 Base Realizado'!$B42) -> 0 | N42: =SUMIFS('B. Despesa'!$H$5:$H$1048576,'B. Despesa'!$I$5:$I$1048576,'01 Base Realizado'!N$5,'B. Despesa'!$K$5:$K$1048576,'01 Base Realizado'!$B42) -> 0 | O42: =SUMIFS('B. Despesa'!$H$5:$H$1048576,'B. Despesa'!$I$5:$I$1048576,'01 Base Realizado'!O$5,'B. Despesa'!$K$5:$K$1048576,'01 Base Realizado'!$B42) -> 0 | P42: =SUMIFS('B. Despesa'!$H$5:$H$1048576,'B. Despesa'!$I$5:$I$1048576,'01 Base Realizado'!P$5,'B. Despesa'!$K$5:$K$1048576,'01 Base Realizado'!$B42) -> 0 | Q42: =SUMIFS('B. Despesa'!$H$5:$H$1048576,'B. Despesa'!$I$5:$I$1048576,'01 Base Realizado'!Q$5,'B. Despesa'!$K$5:$K$1048576,'01 Base Realizado'!$B42) -> 0 | R42: =SUMIFS('B. Despesa'!$H$5:$H$1048576,'B. Despesa'!$I$5:$I$1048576,'01 Base Realizado'!R$5,'B. Despesa'!$K$5:$K$1048576,'01 Base Realizado'!$B42) -> 0 | T42: -2616448.1
B43: 13º Salário | C43: 5.4.1.02.00004 | D43: =SUMIFS('B. Despesa'!$H:$H,'B. Despesa'!$I:$I,'01 Base Realizado'!D$5,'B. Despesa'!$K:$K,'01 Base Realizado'!$B43) -> 0 | E43: =-D43/D$38 -> 0 | F43: =SUMIFS('B. Despesa'!$H$5:$H$1048576,'B. Despesa'!$I$5:$I$1048576,'01 Base Realizado'!F$5,'B. Despesa'!$K$5:$K$1048576,'01 Base Realizado'!$B43) -> 0 | G43: =-F43/F$38 -> 0 | H43: =SUMIFS('B. Despesa'!$H$5:$H$1048576,'B. Despesa'!$I$5:$I$1048576,'01 Base Realizado'!H$5,'B. Despesa'!$K$5:$K$1048576,'01 Base Realizado'!$B43) -> 0 | I43: =-H43/H$38 -> 0 | J43: =SUMIFS('B. Despesa'!$H$5:$H$1048576,'B. Despesa'!$I$5:$I$1048576,'01 Base Realizado'!J$5,'B. Despesa'!$K$5:$K$1048576,'01 Base Realizado'!$B43) -> 0 | K43: =SUMIFS('B. Despesa'!$H$5:$H$1048576,'B. Despesa'!$I$5:$I$1048576,'01 Base Realizado'!K$5,'B. Despesa'!$K$5:$K$1048576,'01 Base Realizado'!$B43) -> 0 | L43: =SUMIFS('B. Despesa'!$H$5:$H$1048576,'B. Despesa'!$I$5:$I$1048576,'01 Base Realizado'!L$5,'B. Despesa'!$K$5:$K$1048576,'01 Base Realizado'!$B43) -> 0 | M43: =SUMIFS('B. Despesa'!$H$5:$H$1048576,'B. Despesa'!$I$5:$I$1048576,'01 Base Realizado'!M$5,'B. Despesa'!$K$5:$K$1048576,'01 Base Realizado'!$B43) -> 0 | N43: =SUMIFS('B. Despesa'!$H$5:$H$1048576,'B. Despesa'!$I$5:$I$1048576,'01 Base Realizado'!N$5,'B. Despesa'!$K$5:$K$1048576,'01 Base Realizado'!$B43) -> 0 | O43: =SUMIFS('B. Despesa'!$H$5:$H$1048576,'B. Despesa'!$I$5:$I$1048576,'01 Base Realizado'!O$5,'B. Despesa'!$K$5:$K$1048576,'01 Base Realizado'!$B43) -> 0 | P43: =SUMIFS('B. Despesa'!$H$5:$H$1048576,'B. Despesa'!$I$5:$I$1048576,'01 Base Realizado'!P$5,'B. Despesa'!$K$5:$K$1048576,'01 Base Realizado'!$B43) -> 0 | Q43: =SUMIFS('B. Despesa'!$H$5:$H$1048576,'B. Despesa'!$I$5:$I$1048576,'01 Base Realizado'!Q$5,'B. Despesa'!$K$5:$K$1048576,'01 Base Realizado'!$B43) -> 0 | R43: =SUMIFS('B. Despesa'!$H$5:$H$1048576,'B. Despesa'!$I$5:$I$1048576,'01 Base Realizado'!R$5,'B. Despesa'!$K$5:$K$1048576,'01 Base Realizado'!$B43) -> 0 | T43: -213951.73
B44: Férias | C44: 5.4.1.02.00005 | D44: =SUMIFS('B. Despesa'!$H:$H,'B. Despesa'!$I:$I,'01 Base Realizado'!D$5,'B. Despesa'!$K:$K,'01 Base Realizado'!$B44) -> 0 | E44: =-D44/D$38 -> 0 | F44: =SUMIFS('B. Despesa'!$H$5:$H$1048576,'B. Despesa'!$I$5:$I$1048576,'01 Base Realizado'!F$5,'B. Despesa'!$K$5:$K$1048576,'01 Base Realizado'!$B44) -> 0 | G44: =-F44/F$38 -> 0 | H44: =SUMIFS('B. Despesa'!$H$5:$H$1048576,'B. Despesa'!$I$5:$I$1048576,'01 Base Realizado'!H$5,'B. Despesa'!$K$5:$K$1048576,'01 Base Realizado'!$B44) -> 0 | I44: =-H44/H$38 -> 0 | J44: =SUMIFS('B. Despesa'!$H$5:$H$1048576,'B. Despesa'!$I$5:$I$1048576,'01 Base Realizado'!J$5,'B. Despesa'!$K$5:$K$1048576,'01 Base Realizado'!$B44) -> 0 | K44: =SUMIFS('B. Despesa'!$H$5:$H$1048576,'B. Despesa'!$I$5:$I$1048576,'01 Base Realizado'!K$5,'B. Despesa'!$K$5:$K$1048576,'01 Base Realizado'!$B44) -> 0 | L44: =SUMIFS('B. Despesa'!$H$5:$H$1048576,'B. Despesa'!$I$5:$I$1048576,'01 Base Realizado'!L$5,'B. Despesa'!$K$5:$K$1048576,'01 Base Realizado'!$B44) -> 0 | M44: =SUMIFS('B. Despesa'!$H$5:$H$1048576,'B. Despesa'!$I$5:$I$1048576,'01 Base Realizado'!M$5,'B. Despesa'!$K$5:$K$1048576,'01 Base Realizado'!$B44) -> 0 | N44: =SUMIFS('B. Despesa'!$H$5:$H$1048576,'B. Despesa'!$I$5:$I$1048576,'01 Base Realizado'!N$5,'B. Despesa'!$K$5:$K$1048576,'01 Base Realizado'!$B44) -> 0 | O44: =SUMIFS('B. Despesa'!$H$5:$H$1048576,'B. Despesa'!$I$5:$I$1048576,'01 Base Realizado'!O$5,'B. Despesa'!$K$5:$K$1048576,'01 Base Realizado'!$B44) -> 0 | P44: =SUMIFS('B. Despesa'!$H$5:$H$1048576,'B. Despesa'!$I$5:$I$1048576,'01 Base Realizado'!P$5,'B. Despesa'!$K$5:$K$1048576,'01 Base Realizado'!$B44) -> 0 | Q44: =SUMIFS('B. Despesa'!$H$5:$H$1048576,'B. Despesa'!$I$5:$I$1048576,'01 Base Realizado'!Q$5,'B. Despesa'!$K$5:$K$1048576,'01 Base Realizado'!$B44) -> 0 | R44: =SUMIFS('B. Despesa'!$H$5:$H$1048576,'B. Despesa'!$I$5:$I$1048576,'01 Base Realizado'!R$5,'B. Despesa'!$K$5:$K$1048576,'01 Base Realizado'!$B44) -> 0 | T44: -144581.06
B45: IR/INSS | C45: 5.4.1.02.00006 | D45: =SUMIFS('B. Despesa'!$H:$H,'B. Despesa'!$I:$I,'01 Base Realizado'!D$5,'B. Despesa'!$K:$K,'01 Base Realizado'!$B45) -> -10278.92 | E45: =-D45/D$38 -> 0.048679923 | F45: =SUMIFS('B. Despesa'!$H$5:$H$1048576,'B. Despesa'!$I$5:$I$1048576,'01 Base Realizado'!F$5,'B. Despesa'!$K$5:$K$1048576,'01 Base Realizado'!$B45) -> -12947.34 | G45: =-F45/F$38 -> 0.049919544 | H45: =SUMIFS('B. Despesa'!$H$5:$H$1048576,'B. Despesa'!$I$5:$I$1048576,'01 Base Realizado'!H$5,'B. Despesa'!$K$5:$K$1048576,'01 Base Realizado'!$B45) -> -16676.19 | I45: =-H45/H$38 -> 0.041755039 | J45: =SUMIFS('B. Despesa'!$H$5:$H$1048576,'B. Despesa'!$I$5:$I$1048576,'01 Base Realizado'!J$5,'B. Despesa'!$K$5:$K$1048576,'01 Base Realizado'!$B45) -> 0 | K45: =SUMIFS('B. Despesa'!$H$5:$H$1048576,'B. Despesa'!$I$5:$I$1048576,'01 Base Realizado'!K$5,'B. Despesa'!$K$5:$K$1048576,'01 Base Realizado'!$B45) -> 0 | L45: =SUMIFS('B. Despesa'!$H$5:$H$1048576,'B. Despesa'!$I$5:$I$1048576,'01 Base Realizado'!L$5,'B. Despesa'!$K$5:$K$1048576,'01 Base Realizado'!$B45) -> 0 | M45: =SUMIFS('B. Despesa'!$H$5:$H$1048576,'B. Despesa'!$I$5:$I$1048576,'01 Base Realizado'!M$5,'B. Despesa'!$K$5:$K$1048576,'01 Base Realizado'!$B45) -> 0 | N45: =SUMIFS('B. Despesa'!$H$5:$H$1048576,'B. Despesa'!$I$5:$I$1048576,'01 Base Realizado'!N$5,'B. Despesa'!$K$5:$K$1048576,'01 Base Realizado'!$B45) -> 0 | O45: =SUMIFS('B. Despesa'!$H$5:$H$1048576,'B. Despesa'!$I$5:$I$1048576,'01 Base Realizado'!O$5,'B. Despesa'!$K$5:$K$1048576,'01 Base Realizado'!$B45) -> 0 | P45: =SUMIFS('B. Despesa'!$H$5:$H$1048576,'B. Despesa'!$I$5:$I$1048576,'01 Base Realizado'!P$5,'B. Despesa'!$K$5:$K$1048576,'01 Base Realizado'!$B45) -> 0 | Q45: =SUMIFS('B. Despesa'!$H$5:$H$1048576,'B. Despesa'!$I$5:$I$1048576,'01 Base Realizado'!Q$5,'B. Despesa'!$K$5:$K$1048576,'01 Base Realizado'!$B45) -> 0 | R45: =SUMIFS('B. Despesa'!$H$5:$H$1048576,'B. Despesa'!$I$5:$I$1048576,'01 Base Realizado'!R$5,'B. Despesa'!$K$5:$K$1048576,'01 Base Realizado'!$B45) -> 0 | T45: -768259.53
B46: FGTS | C46: 5.4.1.02.00007 | D46: =SUMIFS('B. Despesa'!$H:$H,'B. Despesa'!$I:$I,'01 Base Realizado'!D$5,'B. Despesa'!$K:$K,'01 Base Realizado'!$B46) -> -2229.48 | E46: =-D46/D$38 -> 0.010558591 | F46: =SUMIFS('B. Despesa'!$H$5:$H$1048576,'B. Despesa'!$I$5:$I$1048576,'01 Base Realizado'!F$5,'B. Despesa'!$K$5:$K$1048576,'01 Base Realizado'!$B46) -> -2718.39 | G46: =-F46/F$38 -> 0.010480978 | H46: =SUMIFS('B. Despesa'!$H$5:$H$1048576,'B. Despesa'!$I$5:$I$1048576,'01 Base Realizado'!H$5,'B. Despesa'!$K$5:$K$1048576,'01 Base Realizado'!$B46) -> -3529.18 | I46: =-H46/H$38 -> 0.0088366136 | J46: =SUMIFS('B. Despesa'!$H$5:$H$1048576,'B. Despesa'!$I$5:$I$1048576,'01 Base Realizado'!J$5,'B. Despesa'!$K$5:$K$1048576,'01 Base Realizado'!$B46) -> 0 | K46: =SUMIFS('B. Despesa'!$H$5:$H$1048576,'B. Despesa'!$I$5:$I$1048576,'01 Base Realizado'!K$5,'B. Despesa'!$K$5:$K$1048576,'01 Base Realizado'!$B46) -> 0 | L46: =SUMIFS('B. Despesa'!$H$5:$H$1048576,'B. Despesa'!$I$5:$I$1048576,'01 Base Realizado'!L$5,'B. Despesa'!$K$5:$K$1048576,'01 Base Realizado'!$B46) -> 0 | M46: =SUMIFS('B. Despesa'!$H$5:$H$1048576,'B. Despesa'!$I$5:$I$1048576,'01 Base Realizado'!M$5,'B. Despesa'!$K$5:$K$1048576,'01 Base Realizado'!$B46) -> 0 | N46: =SUMIFS('B. Despesa'!$H$5:$H$1048576,'B. Despesa'!$I$5:$I$1048576,'01 Base Realizado'!N$5,'B. Despesa'!$K$5:$K$1048576,'01 Base Realizado'!$B46) -> 0 | O46: =SUMIFS('B. Despesa'!$H$5:$H$1048576,'B. Despesa'!$I$5:$I$1048576,'01 Base Realizado'!O$5,'B. Despesa'!$K$5:$K$1048576,'01 Base Realizado'!$B46) -> 0 | P46: =SUMIFS('B. Despesa'!$H$5:$H$1048576,'B. Despesa'!$I$5:$I$1048576,'01 Base Realizado'!P$5,'B. Despesa'!$K$5:$K$1048576,'01 Base Realizado'!$B46) -> 0 | Q46: =SUMIFS('B. Despesa'!$H$5:$H$1048576,'B. Despesa'!$I$5:$I$1048576,'01 Base Realizado'!Q$5,'B. Despesa'!$K$5:$K$1048576,'01 Base Realizado'!$B46) -> 0 | R46: =SUMIFS('B. Despesa'!$H$5:$H$1048576,'B. Despesa'!$I$5:$I$1048576,'01 Base Realizado'!R$5,'B. Despesa'!$K$5:$K$1048576,'01 Base Realizado'!$B46) -> 0 | T46: -433750.41
B47: Rescisões Trabalhistas | C47: 5.4.1.02.00008 | D47: =SUMIFS('B. Despesa'!$H:$H,'B. Despesa'!$I:$I,'01 Base Realizado'!D$5,'B. Despesa'!$K:$K,'01 Base Realizado'!$B47) -> -2339.06 | E47: =-D47/D$38 -> 0.011077551 | F47: =SUMIFS('B. Despesa'!$H$5:$H$1048576,'B. Despesa'!$I$5:$I$1048576,'01 Base Realizado'!F$5,'B. Despesa'!$K$5:$K$1048576,'01 Base Realizado'!$B47) -> -1236.16 | G47: =-F47/F$38 -> 0.0047661174 | H47: =SUMIFS('B. Despesa'!$H$5:$H$1048576,'B. Despesa'!$I$5:$I$1048576,'01 Base Realizado'!H$5,'B. Despesa'!$K$5:$K$1048576,'01 Base Realizado'!$B47) -> 0 | I47: =-H47/H$38 -> 0 | J47: =SUMIFS('B. Despesa'!$H$5:$H$1048576,'B. Despesa'!$I$5:$I$1048576,'01 Base Realizado'!J$5,'B. Despesa'!$K$5:$K$1048576,'01 Base Realizado'!$B47) -> 0 | K47: =SUMIFS('B. Despesa'!$H$5:$H$1048576,'B. Despesa'!$I$5:$I$1048576,'01 Base Realizado'!K$5,'B. Despesa'!$K$5:$K$1048576,'01 Base Realizado'!$B47) -> 0 | L47: =SUMIFS('B. Despesa'!$H$5:$H$1048576,'B. Despesa'!$I$5:$I$1048576,'01 Base Realizado'!L$5,'B. Despesa'!$K$5:$K$1048576,'01 Base Realizado'!$B47) -> 0 | M47: =SUMIFS('B. Despesa'!$H$5:$H$1048576,'B. Despesa'!$I$5:$I$1048576,'01 Base Realizado'!M$5,'B. Despesa'!$K$5:$K$1048576,'01 Base Realizado'!$B47) -> 0 | N47: =SUMIFS('B. Despesa'!$H$5:$H$1048576,'B. Despesa'!$I$5:$I$1048576,'01 Base Realizado'!N$5,'B. Despesa'!$K$5:$K$1048576,'01 Base Realizado'!$B47) -> 0 | O47: =SUMIFS('B. Despesa'!$H$5:$H$1048576,'B. Despesa'!$I$5:$I$1048576,'01 Base Realizado'!O$5,'B. Despesa'!$K$5:$K$1048576,'01 Base Realizado'!$B47) -> 0 | P47: =SUMIFS('B. Despesa'!$H$5:$H$1048576,'B. Despesa'!$I$5:$I$1048576,'01 Base Realizado'!P$5,'B. Despesa'!$K$5:$K$1048576,'01 Base Realizado'!$B47) -> 0 | Q47: =SUMIFS('B. Despesa'!$H$5:$H$1048576,'B. Despesa'!$I$5:$I$1048576,'01 Base Realizado'!Q$5,'B. Despesa'!$K$5:$K$1048576,'01 Base Realizado'!$B47) -> 0 | R47: =SUMIFS('B. Despesa'!$H$5:$H$1048576,'B. Despesa'!$I$5:$I$1048576,'01 Base Realizado'!R$5,'B. Despesa'!$K$5:$K$1048576,'01 Base Realizado'!$B47) -> 0 | T47: 0 | Y47: Em Jan/26 rescisão da equipe de bar (2), em Fev/26 garçom (1)
B48: Assistência Médica e Social | C48: 5.4.1.02.00009 | D48: =SUMIFS('B. Despesa'!$H:$H,'B. Despesa'!$I:$I,'01 Base Realizado'!D$5,'B. Despesa'!$K:$K,'01 Base Realizado'!$B48) -> -400.64 | E48: =-D48/D$38 -> 0.0018973904 | F48: =SUMIFS('B. Despesa'!$H$5:$H$1048576,'B. Despesa'!$I$5:$I$1048576,'01 Base Realizado'!F$5,'B. Despesa'!$K$5:$K$1048576,'01 Base Realizado'!$B48) -> 0 | G48: =-F48/F$38 -> 0 | H48: =SUMIFS('B. Despesa'!$H$5:$H$1048576,'B. Despesa'!$I$5:$I$1048576,'01 Base Realizado'!H$5,'B. Despesa'!$K$5:$K$1048576,'01 Base Realizado'!$B48) -> 0 | I48: =-H48/H$38 -> 0 | J48: =SUMIFS('B. Despesa'!$H$5:$H$1048576,'B. Despesa'!$I$5:$I$1048576,'01 Base Realizado'!J$5,'B. Despesa'!$K$5:$K$1048576,'01 Base Realizado'!$B48) -> 0 | K48: =SUMIFS('B. Despesa'!$H$5:$H$1048576,'B. Despesa'!$I$5:$I$1048576,'01 Base Realizado'!K$5,'B. Despesa'!$K$5:$K$1048576,'01 Base Realizado'!$B48) -> 0 | L48: =SUMIFS('B. Despesa'!$H$5:$H$1048576,'B. Despesa'!$I$5:$I$1048576,'01 Base Realizado'!L$5,'B. Despesa'!$K$5:$K$1048576,'01 Base Realizado'!$B48) -> 0 | M48: =SUMIFS('B. Despesa'!$H$5:$H$1048576,'B. Despesa'!$I$5:$I$1048576,'01 Base Realizado'!M$5,'B. Despesa'!$K$5:$K$1048576,'01 Base Realizado'!$B48) -> 0 | N48: =SUMIFS('B. Despesa'!$H$5:$H$1048576,'B. Despesa'!$I$5:$I$1048576,'01 Base Realizado'!N$5,'B. Despesa'!$K$5:$K$1048576,'01 Base Realizado'!$B48) -> 0 | O48: =SUMIFS('B. Despesa'!$H$5:$H$1048576,'B. Despesa'!$I$5:$I$1048576,'01 Base Realizado'!O$5,'B. Despesa'!$K$5:$K$1048576,'01 Base Realizado'!$B48) -> 0 | P48: =SUMIFS('B. Despesa'!$H$5:$H$1048576,'B. Despesa'!$I$5:$I$1048576,'01 Base Realizado'!P$5,'B. Despesa'!$K$5:$K$1048576,'01 Base Realizado'!$B48) -> 0 | Q48: =SUMIFS('B. Despesa'!$H$5:$H$1048576,'B. Despesa'!$I$5:$I$1048576,'01 Base Realizado'!Q$5,'B. Despesa'!$K$5:$K$1048576,'01 Base Realizado'!$B48) -> 0 | R48: =SUMIFS('B. Despesa'!$H$5:$H$1048576,'B. Despesa'!$I$5:$I$1048576,'01 Base Realizado'!R$5,'B. Despesa'!$K$5:$K$1048576,'01 Base Realizado'!$B48) -> 0 | T48: -119703.12
...

Sheet 02 Budget x Real %
B4: INDICADORES DE PERFORMANCE
D7: BD | E7: REAL | J7: BD | K7: REAL | M7: BD | N7: REAL | P7: MEDIA BD | Q7: MEDIA REAL | T7: 2026 X META | X7: GAP 1°TRI | Y7: 1° Trimestre
B8: INDICADORES | D8: BD JAN.26 | E8: REAL JAN.26 | F8: JAN/FEV | J8: BD FEV.26 | K8: REAL FEV.26 | M8: BD MAR.26 | N8: REAL MAR.26 | P8: JAN-MAR | Q8: JAN-MAR | T8: RL x BD_Jan'26 | U8: RL x BD_Fev'26 | V8: RL x BD_Mar'26 | X8: JAN-MAR | Y8: Comentários
B9: CMV | D9: =-'03- BD x RE 2026'!BH27 -> 0.32211038 | E9: =-'03- BD x RE 2026'!BI27 -> 0.20728177 | F9: =E9 -> 0.20728177 | J9: =-'03- BD x RE 2026'!BK27 -> 0.32 | K9: =-'03- BD x RE 2026'!BL27 -> 0.30320637 | M9: =-'03- BD x RE 2026'!BN27 -> 0.32153809 | N9: =-'03- BD x RE 2026'!BO27 -> 0.21433756 | P9: =AVERAGE(D9,J9,M9) -> 0.32121616 | Q9: =AVERAGE(E9,K9,N9) -> 0.24160856 | T9: =E9-D9 -> -0.11482861 | U9: =K9-J9 -> -0.016793632 | V9: =N9-M9 -> -0.10720053 | X9: =Q9-P9 -> -0.079607592 | Y9: Utilizamos as planilhas de excel para efetuar os lançamento no sistema, em Abril será 100% plan Everest
B10: PESSOAL | D10: =-'03- BD x RE 2026'!BH36 -> 0.23731058 | E10: =-'03- BD x RE 2026'!BI36 -> 0.23718877 | F10: =E10 -> 0.23718877 | J10: =-'03- BD x RE 2026'!BK36 -> 0.16373678 | K10: =-'03- BD x RE 2026'!BL36 -> 0.1711698 | M10: =-'03- BD x RE 2026'!BN36 -> 0.15358703 | N10: =-'03- BD x RE 2026'!BO36 -> 0.15419608 | P10: =AVERAGE(D10,J10,M10) -> 0.18487813 | Q10: =AVERAGE(E10,K10,N10) -> 0.18751821 | T10: =E10-D10 -> -0.00012180991 | U10: =K10-J10 -> 0.007433025 | V10: =N10-M10 -> 0.000609049 | X10: =Q10-P10 -> 0.002640088
B11: OCUPAÇÃO | D11: =-'03- BD x RE 2026'!BH41 -> 0.06525512 | E11: =-'03- BD x RE 2026'!BI41 -> 0.11271439 | F11: =E11 -> 0.11271439 | J11: =-'03- BD x RE 2026'!BK41 -> 0.054007469 | K11: =-'03- BD x RE 2026'!BL41 -> 0.091762875 | M11: =-'03- BD x RE 2026'!BN41 -> 0.045181447 | N11: =-'03- BD x RE 2026'!BO41 -> 0.059592144 | P11: =AVERAGE(D11,J11,M11) -> 0.054814679 | Q11: =AVERAGE(E11,K11,N11) -> 0.088023135 | T11: =E11-D11 -> 0.047459267 | U11: =K11-J11 -> 0.037755406 | V11: =N11-M11 -> 0.014410698 | X11: =Q11-P11 -> 0.033208457
B12: UTILIDADES/ CONSUMO | D12: =-'03- BD x RE 2026'!BH42 -> 0.013801076 | E12: =-'03- BD x RE 2026'!BI42 -> 0.016614574 | F12: =E12 -> 0.016614574 | J12: =-'03- BD x RE 2026'!BK42 -> 0.0078454467 | K12: =-'03- BD x RE 2026'!BL42 -> 0.0065966711 | M12: =-'03- BD x RE 2026'!BN42 -> 0.0067959865 | N12: =-'03- BD x RE 2026'!BO42 -> 0.045069689 | P12: =AVERAGE(D12,J12,M12) -> 0.0094808364 | Q12: =AVERAGE(E12,K12,N12) -> 0.022760311 | T12: =E12-D12 -> 0.0028134981 | U12: =K12-J12 -> -0.0012487756 | V12: =N12-M12 -> 0.038273702 | X12: =Q12-P12 -> 0.013279475
B13: OPERAÇÃO | D13: =-'03- BD x RE 2026'!BH43 -> 0.17735999 | E13: =-'03- BD x RE 2026'!BI43 -> 0.25035016 | F13: =E13 -> 0.25035016 | J13: =-'03- BD x RE 2026'!BK43 -> 0.18578319 | K13: =-'03- BD x RE 2026'!BL43 -> 0.25533035 | M13: =-'03- BD x RE 2026'!BN43 -> 0.15883713 | N13: =-'03- BD x RE 2026'!BO43 -> 0.20841053 | P13: =AVERAGE(D13,J13,M13) -> 0.17399344 | Q13: =AVERAGE(E13,K13,N13) -> 0.23803035 | T13: =E13-D13 -> 0.072990174 | U13: =K13-J13 -> 0.069547162 | V13: =N13-M13 -> 0.049573402 | X13: =Q13-P13 -> 0.064036913
B14: MANUTENÇÃO E CONSERVAS | D14: =-'03- BD x RE 2026'!BH44 -> 0.016603129 | E14: =-'03- BD x RE 2026'!BI44 -> 0.0044256972 | F14: =E14 -> 0.0044256972 | J14: =-'03- BD x RE 2026'!BK44 -> 0.013741343 | K14: =-'03- BD x RE 2026'!BL44 -> 0.017350123 | M14: =-'03- BD x RE 2026'!BN44 -> 0.011495701 | N14: =-'03- BD x RE 2026'!BO44 -> 0.0024037167 | P14: =AVERAGE(D14,J14,M14) -> 0.013946724 | Q14: =AVERAGE(E14,K14,N14) -> 0.0080598458 | T14: =E14-D14 -> -0.012177432 | U14: =K14-J14 -> 0.0036087807 | V14: =N14-M14 -> -0.0090919847 | X14: =Q14-P14 -> -0.0058868785
B15: ADMINISTRATIVA | D15: =-'03- BD x RE 2026'!BH49 -> 0.062842986 | E15: =-'03- BD x RE 2026'!BI49 -> 0.073454734 | F15: =E15 -> 0.073454734 | J15: =-'03- BD x RE 2026'!BK49 -> 0.04911807 | K15: =-'03- BD x RE 2026'!BL49 -> 0.058340137 | M15: =-'03- BD x RE 2026'!BN49 -> 0.042302331 | N15: =-'03- BD x RE 2026'!BO49 -> 0.037791836 | P15: =AVERAGE(D15,J15,M15) -> 0.051421129 | Q15: =AVERAGE(E15,K15,N15) -> 0.056528902 | T15: =E15-D15 -> 0.010611748 | U15: =K15-J15 -> 0.0092220673 | V15: =N15-M15 -> -0.0045104955 | X15: =Q15-P15 -> 0.0051077732
B16: MARKETING | D16: =-'03- BD x RE 2026'!BH50 -> 0.046393338 | E16: =-'03- BD x RE 2026'!BI50 -> 0.040255138 | F16: =E16 -> 0.040255138 | J16: =-'03- BD x RE 2026'!BK50 -> 0.030163746 | K16: =-'03- BD x RE 2026'!BL50 -> 0.0057833745 | M16: =-'03- BD x RE 2026'!BN50 -> 0.030281182 | N16: =-'03- BD x RE 2026'!BO50 -> 0.04777387 | P16: =AVERAGE(D16,J16,M16) -> 0.035612755 | Q16: =AVERAGE(E16,K16,N16) -> 0.031270794 | T16: =E16-D16 -> -0.0061381998 | U16: =K16-J16 -> -0.024380372 | V16: =N16-M16 -> 0.017492688 | X16: =Q16-P16 -> -0.0043419611
B17: TX CARTÕES | D17: =-'03- BD x RE 2026'!BH51 -> 0.026379729 | E17: =-'03- BD x RE 2026'!BI51 -> 0.030902449 | F17: =E17 -> 0.030902449 | J17: =-'03- BD x RE 2026'!BK51 -> 0.015710284 | K17: =-'03- BD x RE 2026'!BL51 -> 0.027070703 | M17: =-'03- BD x RE 2026'!BN51 -> 0.015771449 | N17: =-'03- BD x RE 2026'!BO51 -> 0.025284496 | P17: =AVERAGE(D17,J17,M17) -> 0.019287154 | Q17: =AVERAGE(E17,K17,N17) -> 0.027752549 | T17: =E17-D17 -> 0.0045227194 | U17: =K17-J17 -> 0.011360419 | V17: =N17-M17 -> 0.009513047 | X17: =Q17-P17 -> 0.0084653952
B19: EBITDA | D19: ='02-Res M'!D30 -> 0.03194368 | E19: ='02-Res M'!F30 -> 0.026812326 | F19: =E19 -> 0.026812326 | J19: ='02-Res M'!H30 -> 0.15989367 | K19: ='02-Res M'!J30 -> 0.063389594 | M19: ='02-Res M'!L30 -> 0.21420966 | N19: ='02-Res M'!N30 -> 0.20514008 | P19: =AVERAGE(D19,J19,M19) -> 0.135349 | Q19: =AVERAGE(E19,K19,N19) -> 0.098447335 | T19: =E19-D19 -> -0.0051313537 | U19: =K19-J19 -> -0.09650408 | V19: =N19-M19 -> -0.0090695734 | X19: =Q19-P19 -> -0.036901669
B20: RESULTADO LÍQUIDO | D20: ='02-Res M'!D41 -> 0.030937085 | E20: ='02-Res M'!F41 -> 0.026282806 | F20: =E20 -> 0.026282806 | J20: ='02-Res M'!H41 -> 0.15888822 | K20: ='02-Res M'!J41 -> 0.062853244 | M20: ='02-Res M'!L41 -> 0.21320028 | N20: ='02-Res M'!N41 -> 0.20507741 | P20: =AVERAGE(D20,J20,M20) -> 0.13434186 | Q20: =AVERAGE(E20,K20,N20) -> 0.098071154 | T20: =E20-D20 -> -0.0046542796 | U20: =K20-J20 -> -0.096034972 | V20: =N20-M20 -> -0.0081228726 | X20: =Q20-P20 -> -0.036270708
B22: COMPARATIVOS | D22: BUDGET | E22: REAL | J22: BUDGET | K22: REAL | M22: BUDGET | N22: REAL | P22: Total. BD Tri | Q22: Total Real Tri | X22: 1º TRI
B24: ='02-Res M'!B15 -> Receita Líquida | D24: ='03- BD x RE 2026'!D23 -> 288100 | E24: ='03- BD x RE 2026'!E23 -> 211153.17 | J24: ='03- BD x RE 2026'!G23 -> 348100 | K24: ='03- BD x RE 2026'!H23 -> 259364.15 | M24: ='03- BD x RE 2026'!J23 -> 416100 | N24: ='03- BD x RE 2026'!K23 -> 399381.5 | P24: =SUM(D24,J24,M24) -> 1052300 | Q24: =SUM(E24,K24,N24) -> 869898.82 | X24: =Q24-P24 -> -182401.18
B26: Resultado Líquido BD x REAL | D26: ='03- BD x RE 2026'!D64 -> 8912.9742 | E26: ='03- BD x RE 2026'!E64 -> 5549.6977 | J26: ='03- BD x RE 2026'!G64 -> 55308.988 | K26: ='03- BD x RE 2026'!H64 -> 16301.878 | M26: ='03- BD x RE 2026'!J64 -> 88712.638 | N26: ='03- BD x RE 2026'!K64 -> 81904.124 | P26: =SUM(D26,J26,M26) -> 152934.6 | Q26: =SUM(E26,K26,N26) -> 103755.7 | X26: =Q26-P26 -> -49178.9
AQ32: O descolamento percetual do real x budguet é devido o valor do faturamento te defit de 47%, concequentimete o impacto percetualmete aumentou porém em valor nomenal está em linha com o budguet

Sheet 02-Res M
B4: COMPARATIVO REAL VS ORÇAMENTO 2026 | W4: INDICES
D6: BD JAN'26 | F6: REAL JAN'26 | H6: BD FEV'26 | J6: REAL FEV'26 | L6: BD MAR26 | N6: BD MAR26 | P6: VAR REAL X BD | S6: V' RE X BD FEV26 | U6: V' RE X BD MAR/26 | W6: PARTICIPAÇÃO
B8: Clientes | D8: ='03- BD x RE 2026'!D7/1000 -> 0 | F8: ='03- BD x RE 2026'!E7/1000 -> 4.761 | H8: ='[1]03- BD x RE 2026'!G7/1000 -> 7.8601684 | J8: ='[1]03- BD x RE 2026'!H7/1000 -> 4.661 | L8: ='[1]03- BD x RE 2026'!J7/1000 -> 7.9214504 | N8: ='[1]03- BD x RE 2026'!K7/1000 -> 6.592 | P8: =IF(ISERROR($F8/D8-1),"-",($F8/D8-1)) -> - | S8: =IF(ISERROR($J8/J8-1),"-",($H8/J8-1)) -> 0.68636953 | U8: =IF(ISERROR($L8/N8-1),"-",($L8/N8-1)) -> 0.20167633
B9: Ticket Médio FB | D9: =IF(ISERROR(D11/D8),0,(D11/D8)) -> 0 | F9: =IF(ISERROR(F11/F8),0,(F11/F8)) -> 44.447429 | H9: =IF(ISERROR(H11/H8),0,(H11/H8)) -> 44.528308 | J9: =IF(ISERROR(J11/J8),0,(J11/J8)) -> 55.821384 | L9: =IF(ISERROR(L11/L8),0,(L11/L8)) -> 53.020594 | N9: =IF(ISERROR(N11/N8),0,(N11/N8)) -> 60.980869 | P9: =IF(ISERROR($F9/D9-1),"-",($F9/D9-1)) -> - | S9: =IF(ISERROR($H9/J9-1),"-",($H9/J9-1)) -> -0.20230734 | U9: =IF(ISERROR($L9/N9-1),"-",($L9/N9-1)) -> -0.13053726
S10: =IF(ISERROR($H10/J10-1),"-",($H10/J10-1)) -> - | U10: =IF(ISERROR($H10/K10-1),"-",($H10/K10-1)) -> -
B11: Faturamento Bruto | D11: ='03- BD x RE 2026'!D10/1000 -> 290 | F11: ='03- BD x RE 2026'!E10/1000 -> 211.61421 | H11: ='03- BD x RE 2026'!G10/1000 -> 350 | J11: ='03- BD x RE 2026'!H10/1000 -> 260.18347 | L11: ='03- BD x RE 2026'!J10/1000 -> 420 | N11: ='03- BD x RE 2026'!K10/1000 -> 401.98589 | P11: =IF(ISERROR($F11/D11-1),"-",($F11/D11-1)) -> -0.27029583 | S11: =IF(ISERROR($H11/J11-1),"-",($H11/J11-1)) -> 0.3452046 | U11: =IF(ISERROR($L11/N11-1),"-",($L11/N11-1)) -> 0.044812792 | W11: JAN'26 | AD11: FEV'26 | AH11: Mar'26
S12: =IF(ISERROR($H12/J12-1),"-",($H12/J12-1)) -> -
B13: Impostos (ICMS/PIS/COFINS) | D13: ='03- BD x RE 2026'!D18/1000 -> -1.9 | F13: ='03- BD x RE 2026'!E18/1000 -> -0.46104 | H13: ='03- BD x RE 2026'!G18/1000 -> -1.9 | J13: ='03- BD x RE 2026'!H18/1000 -> -0.81932 | L13: ='03- BD x RE 2026'!J18/1000 -> -3.9 | N13: ='03- BD x RE 2026'!K18/1000 -> -2.60439 | P13: =IF(ISERROR($F13/D13-1),"-",($F13/D13-1)) -> -0.75734737 | S13: =IF(ISERROR($H13/J13-1),"-",($H13/J13-1)) -> 1.3189962 | U13: =IF(ISERROR($L13/N13-1),"-",($L13/N13-1)) -> 0.49747158
S14: =IF(ISERROR($H14/J14-1),"-",($H14/J14-1)) -> -
B15: Receita Líquida | D15: =D11+D13 -> 288.1 | F15: =F11+F13 -> 211.15317 | H15: =H11+H13 -> 348.1 | J15: =J11+J13 -> 259.36415 | L15: =L11+L13 -> 416.1 | N15: =N11+N13 -> 399.3815 | P15: =IF(ISERROR($F15/D15-1),"-",($F15/D15-1)) -> -0.26708376 | S15: =IF(ISERROR($H15/J15-1),"-",($H15/J15-1)) -> 0.34212843 | U15: =IF(ISERROR($L15/N15-1),"-",($L15/N15-1)) -> 0.041860978 | W15: PART% BD | Y15: PART% REAL | AD15: PART% BD | AF15: PART% REAL | AH15: PART% BD | AJ15: PART% REAL
S16: =IF(ISERROR($H16/J16-1),"-",($H16/J16-1)) -> -
B17: ='[2]2 DRE '!A27 -> CUSTOS/DESPESAS | D17: =SUM(D18:D23) -> -239.82604 | F17: =SUM(F18:F23) -> -174.95631 | H17: =SUM(H18:H23) -> -259.37426 | J17: =SUM(J18:J23) -> -219.27065 | L17: =SUM(L18:L23) -> -290.20286 | N17: =SUM(N18:N23) -> -273.18083 | P17: =IF(ISERROR($F17/D17-1),"-",($F17/D17-1)) -> -0.27048659 | S17: =IF(ISERROR($H17/J17-1),"-",($H17/J17-1)) -> 0.18289548 | U17: =IF(ISERROR($L17/N17-1),"-",($L17/N17-1)) -> 0.062310508 | W17: =IF(ISERROR($D17/$D$15),"-",($D17/$D$15)) -> -0.83244027 | Y17: =IF(ISERROR(F17/F$15),"-",(F17/F$15)) -> -0.82857535 | AA17: Var | AC17: Impacto | AD17: =IF(ISERROR($H17/$H$15),"-",($H17/$H$15)) -> -0.74511423 | AF17: =IF(ISERROR($J17/$J$15),"-",($J17/$J$15)) -> -0.84541619 | AH17: =IF(ISERROR($L17/$L$15),"-",($L17/$L$15)) -> -0.69743538 | AJ17: =IF(ISERROR($N17/$N$15),"-",($N17/$N$15)) -> -0.68400971
B18: CMV | D18: ='03- BD x RE 2026'!D27/1000 -> -92.8 | F18: ='03- BD x RE 2026'!E27/1000 -> -43.768202 | H18: ='03- BD x RE 2026'!G27/1000 -> -111.392 | J18: ='03- BD x RE 2026'!H27/1000 -> -78.640862 | L18: ='03- BD x RE 2026'!J27/1000 -> -133.792 | N18: ='03- BD x RE 2026'!K27/1000 -> -85.602456 | P18: =IF(ISERROR($F18/D18-1),"-",($F18/D18-1)) -> -0.52835989 | S18: =IF(ISERROR($H18/J18-1),"-",($H18/J18-1)) -> 0.41646464 | U18: =IF(ISERROR($L18/N18-1),"-",($L18/N18-1)) -> 0.56294581 | W18: =IF(ISERROR($D18/$D$15),"-",($D18/$D$15)) -> -0.32211038 | Y18: =IF(ISERROR(F18/F$15),"-",(F18/F$15)) -> -0.20728177 | AA18: =Y18-W18 -> 0.11482861 | AC18: =-Y18*AA18 -> 0.023801877 | AD18: =IF(ISERROR($H18/$H$15),"-",($H18/$H$15)) -> -0.32 | AF18: =IF(ISERROR(J18/J$15),"-",(J18/J$15)) -> -0.30320637 | AH18: =IF(ISERROR($L18/$L$15),"-",($L18/$L$15)) -> -0.32153809 | AJ18: =IF(ISERROR($N18/$N$15),"-",($N18/$N$15)) -> -0.21433756
B19: Pessoal | D19: ='03- BD x RE 2026'!D36/1000 -> -68.369177 | F19: ='03- BD x RE 2026'!E36/1000 -> -50.08316 | H19: ='03- BD x RE 2026'!G36/1000 -> -56.996772 | J19: ='03- BD x RE 2026'!H36/1000 -> -44.39531 | L19: ='03- BD x RE 2026'!J36/1000 -> -63.907562 | N19: ='03- BD x RE 2026'!K36/1000 -> -61.58306 | P19: =IF(ISERROR($F19/D19-1),"-",($F19/D19-1)) -> -0.26745996 | S19: =IF(ISERROR($H19/J19-1),"-",($H19/J19-1)) -> 0.28384669 | U19: =IF(ISERROR($L19/N19-1),"-",($L19/N19-1)) -> 0.037745799 | W19: =IF(ISERROR($D19/$D$15),"-",($D19/$D$15)) -> -0.23731058 | Y19: =IF(ISERROR(F19/F$15),"-",(F19/F$15)) -> -0.23718877 | AA19: =Y19-W19 -> 0.00012180991 | AC19: =-Y19*AA19 -> 2.8891944e-05 | AD19: =IF(ISERROR($H19/$H$15),"-",($H19/$H$15)) -> -0.16373678 | AF19: =IF(ISERROR(J19/J$15),"-",(J19/J$15)) -> -0.1711698 | AH19: =IF(ISERROR($L19/$L$15),"-",($L19/$L$15)) -> -0.15358703 | AJ19: =IF(ISERROR($N19/$N$15),"-",($N19/$N$15)) -> -0.15419608
B20: Ocupação | D20: ='03- BD x RE 2026'!D41/1000 -> -18.8 | F20: ='03- BD x RE 2026'!E41/1000 -> -23.8 | H20: ='03- BD x RE 2026'!G41/1000 -> -18.8 | J20: ='03- BD x RE 2026'!H41/1000 -> -23.8 | L20: ='03- BD x RE 2026'!J41/1000 -> -18.8 | N20: ='03- BD x RE 2026'!K41/1000 -> -23.8 | P20: =IF(ISERROR($F20/D20-1),"-",($F20/D20-1)) -> 0.26595745 | S20: =IF(ISERROR($H20/J20-1),"-",($H20/J20-1)) -> -0.21008403 | U20: =IF(ISERROR($L20/N20-1),"-",($L20/N20-1)) -> -0.21008403 | W20: =IF(ISERROR($D20/$D$15),"-",($D20/$D$15)) -> -0.06525512 | Y20: =IF(ISERROR(F20/F$15),"-",(F20/F$15)) -> -0.11271439 | AA20: =Y20-W20 -> -0.047459267 | AC20: =-Y20*AA20 -> -0.0053493421 | AD20: =IF(ISERROR($H20/$H$15),"-",($H20/$H$15)) -> -0.054007469 | AF20: =IF(ISERROR(J20/J$15),"-",(J20/J$15)) -> -0.091762875 | AH20: =IF(ISERROR($L20/$L$15),"-",($L20/$L$15)) -> -0.045181447 | AJ20: =IF(ISERROR($N20/$N$15),"-",($N20/$N$15)) -> -0.059592144
B21: Utilidades/ Consumo | D21: ='03- BD x RE 2026'!D42/1000 -> -3.97609 | F21: ='03- BD x RE 2026'!E42/1000 -> -3.50822 | H21: ='03- BD x RE 2026'!G42/1000 -> -2.731 | J21: ='03- BD x RE 2026'!H42/1000 -> -1.71094 | L21: ='03- BD x RE 2026'!J42/1000 -> -2.82781 | N21: ='03- BD x RE 2026'!K42/1000 -> -18 | P21: =IF(ISERROR($F21/D21-1),"-",($F21/D21-1)) -> -0.11767088 | S21: =IF(ISERROR($H21/J21-1),"-",($H21/J21-1)) -> 0.59619858 | U21: =IF(ISERROR($L21/N21-1),"-",($L21/N21-1)) -> -0.84289944 | W21: =IF(ISERROR($D21/$D$15),"-",($D21/$D$15)) -> -0.013801076 | Y21: =IF(ISERROR(F21/F$15),"-",(F21/F$15)) -> -0.016614574 | AA21: =Y21-W21 -> -0.0028134981 | AC21: =-Y21*AA21 -> -4.6745073e-05 | AD21: =IF(ISERROR($H21/$H$15),"-",($H21/$H$15)) -> -0.0078454467 | AF21: =IF(ISERROR(J21/J$15),"-",(J21/J$15)) -> -0.0065966711 | AH21: =IF(ISERROR($L21/$L$15),"-",($L21/$L$15)) -> -0.0067959865 | AJ21: =IF(ISERROR($N21/$N$15),"-",($N21/$N$15)) -> -0.045069689
B22: Operação | D22: ='03- BD x RE 2026'!D43/1000 -> -51.097412 | F22: ='03- BD x RE 2026'!E43/1000 -> -52.86223 | H22: ='03- BD x RE 2026'!G43/1000 -> -64.671129 | J22: ='03- BD x RE 2026'!H43/1000 -> -66.22354 | L22: ='03- BD x RE 2026'!J43/1000 -> -66.092129 | N22: ='03- BD x RE 2026'!K43/1000 -> -83.23531 | P22: =IF(ISERROR($F22/D22-1),"-",($F22/D22-1)) -> 0.0345383 | S22: =IF(ISERROR($H22/J22-1),"-",($H22/J22-1)) -> -0.023441986 | U22: =IF(ISERROR($L22/N22-1),"-",($L22/N22-1)) -> -0.20596044 | W22: =IF(ISERROR($D22/$D$15),"-",($D22/$D$15)) -> -0.17735999 | Y22: =IF(ISERROR(F22/F$15),"-",(F22/F$15)) -> -0.25035016 | AA22: =Y22-W22 -> -0.072990174 | AC22: =-Y22*AA22 -> -0.018273102 | AD22: =IF(ISERROR($H22/$H$15),"-",($H22/$H$15)) -> -0.18578319 | AF22: =IF(ISERROR(J22/J$15),"-",(J22/J$15)) -> -0.25533035 | AH22: =IF(ISERROR($L22/$L$15),"-",($L22/$L$15)) -> -0.15883713 | AJ22: =IF(ISERROR($N22/$N$15),"-",($N22/$N$15)) -> -0.20841053
B23: Manutenção e Conservação | D23: ='03- BD x RE 2026'!D44/1000 -> -4.7833614 | F23: ='03- BD x RE 2026'!E44/1000 -> -0.9345 | H23: ='03- BD x RE 2026'!G44/1000 -> -4.7833614 | J23: ='03- BD x RE 2026'!H44/1000 -> -4.5 | L23: ='03- BD x RE 2026'!J44/1000 -> -4.7833614 | N23: ='03- BD x RE 2026'!K44/1000 -> -0.96 | P23: =IF(ISERROR($F23/D23-1),"-",($F23/D23-1)) -> -0.80463529 | S23: =IF(ISERROR($H23/J23-1),"-",($H23/J23-1)) -> 0.062969198 | U23: =IF(ISERROR($L23/N23-1),"-",($L23/N23-1)) -> 3.9826681 | W23: =IF(ISERROR($D23/$D$15),"-",($D23/$D$15)) -> -0.016603129 | Y23: =IF(ISERROR(F23/F$15),"-",(F23/F$15)) -> -0.0044256972 | AA23: =Y23-W23 -> 0.012177432 | AC23: =-Y23*AA23 -> 5.3893625e-05 | AD23: =IF(ISERROR($H23/$H$15),"-",($H23/$H$15)) -> -0.013741343 | AF23: =IF(ISERROR(J23/J$15),"-",(J23/J$15)) -> -0.017350123 | AH23: =IF(ISERROR($L23/$L$15),"-",($L23/$L$15)) -> -0.011495701 | AJ23: =IF(ISERROR($N23/$N$15),"-",($N23/$N$15)) -> -0.0024037167
B24: ='[2]2 DRE '!A52 -> DESPESAS ADMINISTRATIVAS | D24: =SUM(D25:D27) -> -39.070985 | F24: =SUM(F25:F27) -> -30.53535 | H24: =SUM(H25:H27) -> -33.06675 | J24: =SUM(J25:J27) -> -23.65251 | L24: =SUM(L25:L27) -> -36.7645 | N24: =SUM(N25:N27) -> -44.27152 | P24: =IF(ISERROR($F24/D24-1),"-",($F24/D24-1)) -> -0.2184648 | S24: =IF(ISERROR($H24/J24-1),"-",($H24/J24-1)) -> 0.39802287 | U24: =IF(ISERROR($L24/N24-1),"-",($L24/N24-1)) -> -0.1695677 | W24: =IF(ISERROR($D24/$D$15),"-",($D24/$D$15)) -> -0.13561605 | Y24: =IF(ISERROR(F24/F$15),"-",(F24/F$15)) -> -0.14461232 | AA24: =Y24-W24 -> -0.0089962676 | AC24: =AA24-Y24 -> 0.13561605 | AD24: =IF(ISERROR($H24/$H$15),"-",($H24/$H$15)) -> -0.0949921 | AF24: =IF(ISERROR($J24/$J$15),"-",($J24/$J$15)) -> -0.091194215 | AH24: =IF(ISERROR($L24/$L$15),"-",($L24/$L$15)) -> -0.088354963 | AJ24: =IF(ISERROR($N24/$N$15),"-",($N24/$N$15)) -> -0.1108502
